[2022-03-23 15:02:52,405] {taskinstance.py:1032} INFO - Dependencies all met for <TaskInstance: dtc_project_ingest.bigquery_external_table_task scheduled__2018-03-02T06:00:00+00:00 [queued]>
[2022-03-23 15:02:52,419] {taskinstance.py:1032} INFO - Dependencies all met for <TaskInstance: dtc_project_ingest.bigquery_external_table_task scheduled__2018-03-02T06:00:00+00:00 [queued]>
[2022-03-23 15:02:52,421] {taskinstance.py:1238} INFO - 
--------------------------------------------------------------------------------
[2022-03-23 15:02:52,421] {taskinstance.py:1239} INFO - Starting attempt 1 of 2
[2022-03-23 15:02:52,422] {taskinstance.py:1240} INFO - 
--------------------------------------------------------------------------------
[2022-03-23 15:02:52,434] {taskinstance.py:1259} INFO - Executing <Task(BigQueryCreateExternalTableOperator): bigquery_external_table_task> on 2018-03-02 06:00:00+00:00
[2022-03-23 15:02:52,440] {standard_task_runner.py:52} INFO - Started process 704 to run task
[2022-03-23 15:02:52,446] {standard_task_runner.py:76} INFO - Running: ['***', 'tasks', 'run', 'dtc_project_ingest', 'bigquery_external_table_task', 'scheduled__2018-03-02T06:00:00+00:00', '--job-id', '859', '--raw', '--subdir', 'DAGS_FOLDER/project_data_ingestion.py', '--cfg-path', '/tmp/tmpx3hrvnc3', '--error-file', '/tmp/tmp2vx3rrg_']
[2022-03-23 15:02:52,447] {standard_task_runner.py:77} INFO - Job 859: Subtask bigquery_external_table_task
[2022-03-23 15:02:52,523] {logging_mixin.py:109} INFO - Running <TaskInstance: dtc_project_ingest.bigquery_external_table_task scheduled__2018-03-02T06:00:00+00:00 [running]> on host 7127e26385ba
[2022-03-23 15:02:52,584] {taskinstance.py:1426} INFO - Exporting the following env vars:
AIRFLOW_CTX_DAG_OWNER=***
AIRFLOW_CTX_DAG_ID=dtc_project_ingest
AIRFLOW_CTX_TASK_ID=bigquery_external_table_task
AIRFLOW_CTX_EXECUTION_DATE=2018-03-02T06:00:00+00:00
AIRFLOW_CTX_DAG_RUN_ID=scheduled__2018-03-02T06:00:00+00:00
[2022-03-23 15:02:52,587] {crypto.py:82} WARNING - empty cryptography key - values will not be stored encrypted.
[2022-03-23 15:02:53,914] {taskinstance.py:1700} ERROR - Task failed with exception
Traceback (most recent call last):
  File "/home/airflow/.local/lib/python3.7/site-packages/airflow/models/taskinstance.py", line 1329, in _run_raw_task
    self._execute_task_with_callbacks(context)
  File "/home/airflow/.local/lib/python3.7/site-packages/airflow/models/taskinstance.py", line 1455, in _execute_task_with_callbacks
    result = self._execute_task(context, self.task)
  File "/home/airflow/.local/lib/python3.7/site-packages/airflow/models/taskinstance.py", line 1511, in _execute_task
    result = execute_callable(context=context)
  File "/home/airflow/.local/lib/python3.7/site-packages/airflow/providers/google/cloud/operators/bigquery.py", line 1196, in execute
    table_resource=self.table_resource,
  File "/home/airflow/.local/lib/python3.7/site-packages/airflow/providers/google/common/hooks/base_google.py", line 430, in inner_wrapper
    return func(self, *args, **kwargs)
  File "/home/airflow/.local/lib/python3.7/site-packages/airflow/providers/google/cloud/hooks/bigquery.py", line 408, in create_empty_table
    table=table, exists_ok=exists_ok, retry=retry
  File "/home/airflow/.local/lib/python3.7/site-packages/google/cloud/bigquery/client.py", line 755, in create_table
    timeout=timeout,
  File "/home/airflow/.local/lib/python3.7/site-packages/google/cloud/bigquery/client.py", line 782, in _call_api
    return call()
  File "/home/airflow/.local/lib/python3.7/site-packages/google/api_core/retry.py", line 291, in retry_wrapped_func
    on_error=on_error,
  File "/home/airflow/.local/lib/python3.7/site-packages/google/api_core/retry.py", line 189, in retry_target
    return target()
  File "/home/airflow/.local/lib/python3.7/site-packages/google/cloud/_http.py", line 484, in api_request
    raise exceptions.from_http_response(response)
google.api_core.exceptions.BadRequest: 400 POST https://bigquery.googleapis.com/bigquery/v2/projects/healthy-fuze-339218/datasets/citibike_project/tables?prettyPrint=false: Error while reading table: citibike_project, error message: Failed to expand table citibike_project with file pattern gs://dtc_citibike_project/raw/201306-citibike-tripdata.zip: matched no files.
[2022-03-23 15:02:53,936] {taskinstance.py:1277} INFO - Marking task as UP_FOR_RETRY. dag_id=dtc_project_ingest, task_id=bigquery_external_table_task, execution_date=20180302T060000, start_date=20220323T150252, end_date=20220323T150253
[2022-03-23 15:02:54,024] {standard_task_runner.py:92} ERROR - Failed to execute job 859 for task bigquery_external_table_task
Traceback (most recent call last):
  File "/home/airflow/.local/lib/python3.7/site-packages/airflow/task/task_runner/standard_task_runner.py", line 85, in _start_by_fork
    args.func(args, dag=self.dag)
  File "/home/airflow/.local/lib/python3.7/site-packages/airflow/cli/cli_parser.py", line 48, in command
    return func(*args, **kwargs)
  File "/home/airflow/.local/lib/python3.7/site-packages/airflow/utils/cli.py", line 92, in wrapper
    return f(*args, **kwargs)
  File "/home/airflow/.local/lib/python3.7/site-packages/airflow/cli/commands/task_command.py", line 298, in task_run
    _run_task_by_selected_method(args, dag, ti)
  File "/home/airflow/.local/lib/python3.7/site-packages/airflow/cli/commands/task_command.py", line 107, in _run_task_by_selected_method
    _run_raw_task(args, ti)
  File "/home/airflow/.local/lib/python3.7/site-packages/airflow/cli/commands/task_command.py", line 184, in _run_raw_task
    error_file=args.error_file,
  File "/home/airflow/.local/lib/python3.7/site-packages/airflow/utils/session.py", line 70, in wrapper
    return func(*args, session=session, **kwargs)
  File "/home/airflow/.local/lib/python3.7/site-packages/airflow/models/taskinstance.py", line 1329, in _run_raw_task
    self._execute_task_with_callbacks(context)
  File "/home/airflow/.local/lib/python3.7/site-packages/airflow/models/taskinstance.py", line 1455, in _execute_task_with_callbacks
    result = self._execute_task(context, self.task)
  File "/home/airflow/.local/lib/python3.7/site-packages/airflow/models/taskinstance.py", line 1511, in _execute_task
    result = execute_callable(context=context)
  File "/home/airflow/.local/lib/python3.7/site-packages/airflow/providers/google/cloud/operators/bigquery.py", line 1196, in execute
    table_resource=self.table_resource,
  File "/home/airflow/.local/lib/python3.7/site-packages/airflow/providers/google/common/hooks/base_google.py", line 430, in inner_wrapper
    return func(self, *args, **kwargs)
  File "/home/airflow/.local/lib/python3.7/site-packages/airflow/providers/google/cloud/hooks/bigquery.py", line 408, in create_empty_table
    table=table, exists_ok=exists_ok, retry=retry
  File "/home/airflow/.local/lib/python3.7/site-packages/google/cloud/bigquery/client.py", line 755, in create_table
    timeout=timeout,
  File "/home/airflow/.local/lib/python3.7/site-packages/google/cloud/bigquery/client.py", line 782, in _call_api
    return call()
  File "/home/airflow/.local/lib/python3.7/site-packages/google/api_core/retry.py", line 291, in retry_wrapped_func
    on_error=on_error,
  File "/home/airflow/.local/lib/python3.7/site-packages/google/api_core/retry.py", line 189, in retry_target
    return target()
  File "/home/airflow/.local/lib/python3.7/site-packages/google/cloud/_http.py", line 484, in api_request
    raise exceptions.from_http_response(response)
google.api_core.exceptions.BadRequest: 400 POST https://bigquery.googleapis.com/bigquery/v2/projects/healthy-fuze-339218/datasets/citibike_project/tables?prettyPrint=false: Error while reading table: citibike_project, error message: Failed to expand table citibike_project with file pattern gs://dtc_citibike_project/raw/201306-citibike-tripdata.zip: matched no files.
[2022-03-23 15:02:54,049] {local_task_job.py:154} INFO - Task exited with return code 1
[2022-03-23 15:02:54,096] {local_task_job.py:264} INFO - 0 downstream tasks scheduled from follow-on schedule check
[2022-03-23 15:18:52,983] {taskinstance.py:1032} INFO - Dependencies all met for <TaskInstance: dtc_project_ingest.bigquery_external_table_task scheduled__2018-03-02T06:00:00+00:00 [queued]>
[2022-03-23 15:18:53,002] {taskinstance.py:1032} INFO - Dependencies all met for <TaskInstance: dtc_project_ingest.bigquery_external_table_task scheduled__2018-03-02T06:00:00+00:00 [queued]>
[2022-03-23 15:18:53,003] {taskinstance.py:1238} INFO - 
--------------------------------------------------------------------------------
[2022-03-23 15:18:53,005] {taskinstance.py:1239} INFO - Starting attempt 1 of 2
[2022-03-23 15:18:53,006] {taskinstance.py:1240} INFO - 
--------------------------------------------------------------------------------
[2022-03-23 15:18:53,026] {taskinstance.py:1259} INFO - Executing <Task(BigQueryCreateExternalTableOperator): bigquery_external_table_task> on 2018-03-02 06:00:00+00:00
[2022-03-23 15:18:53,036] {standard_task_runner.py:52} INFO - Started process 1503 to run task
[2022-03-23 15:18:53,043] {standard_task_runner.py:76} INFO - Running: ['***', 'tasks', 'run', 'dtc_project_ingest', 'bigquery_external_table_task', 'scheduled__2018-03-02T06:00:00+00:00', '--job-id', '877', '--raw', '--subdir', 'DAGS_FOLDER/project_data_ingestion.py', '--cfg-path', '/tmp/tmpb43ns2fo', '--error-file', '/tmp/tmpvft0wan6']
[2022-03-23 15:18:53,045] {standard_task_runner.py:77} INFO - Job 877: Subtask bigquery_external_table_task
[2022-03-23 15:18:53,143] {logging_mixin.py:109} INFO - Running <TaskInstance: dtc_project_ingest.bigquery_external_table_task scheduled__2018-03-02T06:00:00+00:00 [running]> on host 7127e26385ba
[2022-03-23 15:18:53,243] {warnings.py:110} WARNING - /home/***/.local/lib/python3.7/site-packages/***/utils/context.py:152: AirflowContextDeprecationWarning: Accessing 'execution_date' from the template is deprecated and will be removed in a future version. Please use 'data_interval_start' or 'logical_date' instead.
  warnings.warn(_create_deprecation_warning(key, self._deprecation_replacements[key]))

[2022-03-23 15:18:53,330] {taskinstance.py:1426} INFO - Exporting the following env vars:
AIRFLOW_CTX_DAG_OWNER=***
AIRFLOW_CTX_DAG_ID=dtc_project_ingest
AIRFLOW_CTX_TASK_ID=bigquery_external_table_task
AIRFLOW_CTX_EXECUTION_DATE=2018-03-02T06:00:00+00:00
AIRFLOW_CTX_DAG_RUN_ID=scheduled__2018-03-02T06:00:00+00:00
[2022-03-23 15:18:53,338] {crypto.py:82} WARNING - empty cryptography key - values will not be stored encrypted.
[2022-03-23 15:18:54,440] {taskinstance.py:1700} ERROR - Task failed with exception
Traceback (most recent call last):
  File "/home/airflow/.local/lib/python3.7/site-packages/airflow/models/taskinstance.py", line 1329, in _run_raw_task
    self._execute_task_with_callbacks(context)
  File "/home/airflow/.local/lib/python3.7/site-packages/airflow/models/taskinstance.py", line 1455, in _execute_task_with_callbacks
    result = self._execute_task(context, self.task)
  File "/home/airflow/.local/lib/python3.7/site-packages/airflow/models/taskinstance.py", line 1511, in _execute_task
    result = execute_callable(context=context)
  File "/home/airflow/.local/lib/python3.7/site-packages/airflow/providers/google/cloud/operators/bigquery.py", line 1196, in execute
    table_resource=self.table_resource,
  File "/home/airflow/.local/lib/python3.7/site-packages/airflow/providers/google/common/hooks/base_google.py", line 430, in inner_wrapper
    return func(self, *args, **kwargs)
  File "/home/airflow/.local/lib/python3.7/site-packages/airflow/providers/google/cloud/hooks/bigquery.py", line 408, in create_empty_table
    table=table, exists_ok=exists_ok, retry=retry
  File "/home/airflow/.local/lib/python3.7/site-packages/google/cloud/bigquery/client.py", line 755, in create_table
    timeout=timeout,
  File "/home/airflow/.local/lib/python3.7/site-packages/google/cloud/bigquery/client.py", line 782, in _call_api
    return call()
  File "/home/airflow/.local/lib/python3.7/site-packages/google/api_core/retry.py", line 291, in retry_wrapped_func
    on_error=on_error,
  File "/home/airflow/.local/lib/python3.7/site-packages/google/api_core/retry.py", line 189, in retry_target
    return target()
  File "/home/airflow/.local/lib/python3.7/site-packages/google/cloud/_http.py", line 484, in api_request
    raise exceptions.from_http_response(response)
google.api_core.exceptions.BadRequest: 400 POST https://bigquery.googleapis.com/bigquery/v2/projects/healthy-fuze-339218/datasets/citibike_project/tables?prettyPrint=false: Error while reading table: citibike_project, error message: Failed to expand table citibike_project with file pattern gs://dtc_citibike_project/raw//opt/airflow/201803-citibike-tripdata.parquet: matched no files.
[2022-03-23 15:18:54,535] {taskinstance.py:1277} INFO - Marking task as UP_FOR_RETRY. dag_id=dtc_project_ingest, task_id=bigquery_external_table_task, execution_date=20180302T060000, start_date=20220323T151852, end_date=20220323T151854
[2022-03-23 15:18:54,634] {standard_task_runner.py:92} ERROR - Failed to execute job 877 for task bigquery_external_table_task
Traceback (most recent call last):
  File "/home/airflow/.local/lib/python3.7/site-packages/airflow/task/task_runner/standard_task_runner.py", line 85, in _start_by_fork
    args.func(args, dag=self.dag)
  File "/home/airflow/.local/lib/python3.7/site-packages/airflow/cli/cli_parser.py", line 48, in command
    return func(*args, **kwargs)
  File "/home/airflow/.local/lib/python3.7/site-packages/airflow/utils/cli.py", line 92, in wrapper
    return f(*args, **kwargs)
  File "/home/airflow/.local/lib/python3.7/site-packages/airflow/cli/commands/task_command.py", line 298, in task_run
    _run_task_by_selected_method(args, dag, ti)
  File "/home/airflow/.local/lib/python3.7/site-packages/airflow/cli/commands/task_command.py", line 107, in _run_task_by_selected_method
    _run_raw_task(args, ti)
  File "/home/airflow/.local/lib/python3.7/site-packages/airflow/cli/commands/task_command.py", line 184, in _run_raw_task
    error_file=args.error_file,
  File "/home/airflow/.local/lib/python3.7/site-packages/airflow/utils/session.py", line 70, in wrapper
    return func(*args, session=session, **kwargs)
  File "/home/airflow/.local/lib/python3.7/site-packages/airflow/models/taskinstance.py", line 1329, in _run_raw_task
    self._execute_task_with_callbacks(context)
  File "/home/airflow/.local/lib/python3.7/site-packages/airflow/models/taskinstance.py", line 1455, in _execute_task_with_callbacks
    result = self._execute_task(context, self.task)
  File "/home/airflow/.local/lib/python3.7/site-packages/airflow/models/taskinstance.py", line 1511, in _execute_task
    result = execute_callable(context=context)
  File "/home/airflow/.local/lib/python3.7/site-packages/airflow/providers/google/cloud/operators/bigquery.py", line 1196, in execute
    table_resource=self.table_resource,
  File "/home/airflow/.local/lib/python3.7/site-packages/airflow/providers/google/common/hooks/base_google.py", line 430, in inner_wrapper
    return func(self, *args, **kwargs)
  File "/home/airflow/.local/lib/python3.7/site-packages/airflow/providers/google/cloud/hooks/bigquery.py", line 408, in create_empty_table
    table=table, exists_ok=exists_ok, retry=retry
  File "/home/airflow/.local/lib/python3.7/site-packages/google/cloud/bigquery/client.py", line 755, in create_table
    timeout=timeout,
  File "/home/airflow/.local/lib/python3.7/site-packages/google/cloud/bigquery/client.py", line 782, in _call_api
    return call()
  File "/home/airflow/.local/lib/python3.7/site-packages/google/api_core/retry.py", line 291, in retry_wrapped_func
    on_error=on_error,
  File "/home/airflow/.local/lib/python3.7/site-packages/google/api_core/retry.py", line 189, in retry_target
    return target()
  File "/home/airflow/.local/lib/python3.7/site-packages/google/cloud/_http.py", line 484, in api_request
    raise exceptions.from_http_response(response)
google.api_core.exceptions.BadRequest: 400 POST https://bigquery.googleapis.com/bigquery/v2/projects/healthy-fuze-339218/datasets/citibike_project/tables?prettyPrint=false: Error while reading table: citibike_project, error message: Failed to expand table citibike_project with file pattern gs://dtc_citibike_project/raw//opt/airflow/201803-citibike-tripdata.parquet: matched no files.
[2022-03-23 15:18:54,727] {local_task_job.py:154} INFO - Task exited with return code 1
[2022-03-23 15:18:55,148] {local_task_job.py:264} INFO - 0 downstream tasks scheduled from follow-on schedule check
[2022-03-23 15:55:38,077] {taskinstance.py:1032} INFO - Dependencies all met for <TaskInstance: dtc_project_ingest.bigquery_external_table_task scheduled__2018-03-02T06:00:00+00:00 [queued]>
[2022-03-23 15:55:38,089] {taskinstance.py:1032} INFO - Dependencies all met for <TaskInstance: dtc_project_ingest.bigquery_external_table_task scheduled__2018-03-02T06:00:00+00:00 [queued]>
[2022-03-23 15:55:38,090] {taskinstance.py:1238} INFO - 
--------------------------------------------------------------------------------
[2022-03-23 15:55:38,091] {taskinstance.py:1239} INFO - Starting attempt 1 of 2
[2022-03-23 15:55:38,092] {taskinstance.py:1240} INFO - 
--------------------------------------------------------------------------------
[2022-03-23 15:55:38,104] {taskinstance.py:1259} INFO - Executing <Task(BigQueryCreateExternalTableOperator): bigquery_external_table_task> on 2018-03-02 06:00:00+00:00
[2022-03-23 15:55:38,111] {standard_task_runner.py:52} INFO - Started process 3385 to run task
[2022-03-23 15:55:38,115] {standard_task_runner.py:76} INFO - Running: ['***', 'tasks', 'run', 'dtc_project_ingest', 'bigquery_external_table_task', 'scheduled__2018-03-02T06:00:00+00:00', '--job-id', '947', '--raw', '--subdir', 'DAGS_FOLDER/project_data_ingestion.py', '--cfg-path', '/tmp/tmpsn_yj_ba', '--error-file', '/tmp/tmp4i7hrvnl']
[2022-03-23 15:55:38,116] {standard_task_runner.py:77} INFO - Job 947: Subtask bigquery_external_table_task
[2022-03-23 15:55:38,202] {logging_mixin.py:109} INFO - Running <TaskInstance: dtc_project_ingest.bigquery_external_table_task scheduled__2018-03-02T06:00:00+00:00 [running]> on host 7127e26385ba
[2022-03-23 15:55:38,251] {warnings.py:110} WARNING - /home/***/.local/lib/python3.7/site-packages/***/utils/context.py:152: AirflowContextDeprecationWarning: Accessing 'execution_date' from the template is deprecated and will be removed in a future version. Please use 'data_interval_start' or 'logical_date' instead.
  warnings.warn(_create_deprecation_warning(key, self._deprecation_replacements[key]))

[2022-03-23 15:55:38,276] {taskinstance.py:1426} INFO - Exporting the following env vars:
AIRFLOW_CTX_DAG_OWNER=***
AIRFLOW_CTX_DAG_ID=dtc_project_ingest
AIRFLOW_CTX_TASK_ID=bigquery_external_table_task
AIRFLOW_CTX_EXECUTION_DATE=2018-03-02T06:00:00+00:00
AIRFLOW_CTX_DAG_RUN_ID=scheduled__2018-03-02T06:00:00+00:00
[2022-03-23 15:55:38,279] {crypto.py:82} WARNING - empty cryptography key - values will not be stored encrypted.
[2022-03-23 15:55:39,706] {taskinstance.py:1277} INFO - Marking task as SUCCESS. dag_id=dtc_project_ingest, task_id=bigquery_external_table_task, execution_date=20180302T060000, start_date=20220323T155538, end_date=20220323T155539
[2022-03-23 15:55:39,742] {local_task_job.py:154} INFO - Task exited with return code 0
[2022-03-23 15:55:39,779] {local_task_job.py:264} INFO - 1 downstream tasks scheduled from follow-on schedule check
[2022-03-26 10:32:06,495] {taskinstance.py:1032} INFO - Dependencies all met for <TaskInstance: dtc_project_ingest.bigquery_external_table_task scheduled__2018-03-02T06:00:00+00:00 [queued]>
[2022-03-26 10:32:06,509] {taskinstance.py:1032} INFO - Dependencies all met for <TaskInstance: dtc_project_ingest.bigquery_external_table_task scheduled__2018-03-02T06:00:00+00:00 [queued]>
[2022-03-26 10:32:06,510] {taskinstance.py:1238} INFO - 
--------------------------------------------------------------------------------
[2022-03-26 10:32:06,511] {taskinstance.py:1239} INFO - Starting attempt 1 of 2
[2022-03-26 10:32:06,512] {taskinstance.py:1240} INFO - 
--------------------------------------------------------------------------------
[2022-03-26 10:32:06,528] {taskinstance.py:1259} INFO - Executing <Task(BigQueryCreateExternalTableOperator): bigquery_external_table_task> on 2018-03-02 06:00:00+00:00
[2022-03-26 10:32:06,537] {standard_task_runner.py:52} INFO - Started process 5054 to run task
[2022-03-26 10:32:06,542] {standard_task_runner.py:76} INFO - Running: ['***', 'tasks', 'run', 'dtc_project_ingest', 'bigquery_external_table_task', 'scheduled__2018-03-02T06:00:00+00:00', '--job-id', '1302', '--raw', '--subdir', 'DAGS_FOLDER/project_data_ingestion.py', '--cfg-path', '/tmp/tmpqnvzpuho', '--error-file', '/tmp/tmp8ym0rfgk']
[2022-03-26 10:32:06,543] {standard_task_runner.py:77} INFO - Job 1302: Subtask bigquery_external_table_task
[2022-03-26 10:32:06,626] {logging_mixin.py:109} INFO - Running <TaskInstance: dtc_project_ingest.bigquery_external_table_task scheduled__2018-03-02T06:00:00+00:00 [running]> on host c800f4dda314
[2022-03-26 10:32:06,702] {taskinstance.py:1426} INFO - Exporting the following env vars:
AIRFLOW_CTX_DAG_OWNER=***
AIRFLOW_CTX_DAG_ID=dtc_project_ingest
AIRFLOW_CTX_TASK_ID=bigquery_external_table_task
AIRFLOW_CTX_EXECUTION_DATE=2018-03-02T06:00:00+00:00
AIRFLOW_CTX_DAG_RUN_ID=scheduled__2018-03-02T06:00:00+00:00
[2022-03-26 10:32:06,705] {crypto.py:82} WARNING - empty cryptography key - values will not be stored encrypted.
[2022-03-26 10:32:09,113] {taskinstance.py:1277} INFO - Marking task as SUCCESS. dag_id=dtc_project_ingest, task_id=bigquery_external_table_task, execution_date=20180302T060000, start_date=20220326T103206, end_date=20220326T103209
[2022-03-26 10:32:09,217] {local_task_job.py:154} INFO - Task exited with return code 0
[2022-03-26 10:32:09,267] {local_task_job.py:264} INFO - 1 downstream tasks scheduled from follow-on schedule check
