[2022-03-26 10:24:22,661] {taskinstance.py:1032} INFO - Dependencies all met for <TaskInstance: dtc_project_ingest.rm_task scheduled__2020-02-02T06:00:00+00:00 [queued]>
[2022-03-26 10:24:22,680] {taskinstance.py:1032} INFO - Dependencies all met for <TaskInstance: dtc_project_ingest.rm_task scheduled__2020-02-02T06:00:00+00:00 [queued]>
[2022-03-26 10:24:22,683] {taskinstance.py:1238} INFO - 
--------------------------------------------------------------------------------
[2022-03-26 10:24:22,684] {taskinstance.py:1239} INFO - Starting attempt 4 of 5
[2022-03-26 10:24:22,685] {taskinstance.py:1240} INFO - 
--------------------------------------------------------------------------------
[2022-03-26 10:24:22,698] {taskinstance.py:1259} INFO - Executing <Task(BashOperator): rm_task> on 2020-02-02 06:00:00+00:00
[2022-03-26 10:24:22,706] {standard_task_runner.py:52} INFO - Started process 4620 to run task
[2022-03-26 10:24:22,711] {standard_task_runner.py:76} INFO - Running: ['***', 'tasks', 'run', 'dtc_project_ingest', 'rm_task', 'scheduled__2020-02-02T06:00:00+00:00', '--job-id', '1283', '--raw', '--subdir', 'DAGS_FOLDER/project_data_ingestion.py', '--cfg-path', '/tmp/tmpoyrwdisi', '--error-file', '/tmp/tmpvr85ftic']
[2022-03-26 10:24:22,712] {standard_task_runner.py:77} INFO - Job 1283: Subtask rm_task
[2022-03-26 10:24:22,785] {logging_mixin.py:109} INFO - Running <TaskInstance: dtc_project_ingest.rm_task scheduled__2020-02-02T06:00:00+00:00 [running]> on host c800f4dda314
[2022-03-26 10:24:22,831] {warnings.py:110} WARNING - /home/***/.local/lib/python3.7/site-packages/***/utils/context.py:152: AirflowContextDeprecationWarning: Accessing 'execution_date' from the template is deprecated and will be removed in a future version. Please use 'data_interval_start' or 'logical_date' instead.
  warnings.warn(_create_deprecation_warning(key, self._deprecation_replacements[key]))

[2022-03-26 10:24:22,854] {taskinstance.py:1426} INFO - Exporting the following env vars:
AIRFLOW_CTX_DAG_OWNER=***
AIRFLOW_CTX_DAG_ID=dtc_project_ingest
AIRFLOW_CTX_TASK_ID=rm_task
AIRFLOW_CTX_EXECUTION_DATE=2020-02-02T06:00:00+00:00
AIRFLOW_CTX_DAG_RUN_ID=scheduled__2020-02-02T06:00:00+00:00
[2022-03-26 10:24:22,857] {subprocess.py:62} INFO - Tmp dir root location: 
 /tmp
[2022-03-26 10:24:22,858] {subprocess.py:74} INFO - Running command: ['bash', '-c', 'rm /opt/***/202002-citibike-tripdata.csv /opt/***/202002-citibike-tripdata.parquet']
[2022-03-26 10:24:22,872] {subprocess.py:85} INFO - Output:
[2022-03-26 10:24:22,876] {subprocess.py:89} INFO - rm: cannot remove '/opt/***/202002-citibike-tripdata.csv': No such file or directory
[2022-03-26 10:24:22,877] {subprocess.py:89} INFO - rm: cannot remove '/opt/***/202002-citibike-tripdata.parquet': No such file or directory
[2022-03-26 10:24:22,878] {subprocess.py:93} INFO - Command exited with return code 1
[2022-03-26 10:24:22,896] {taskinstance.py:1700} ERROR - Task failed with exception
Traceback (most recent call last):
  File "/home/airflow/.local/lib/python3.7/site-packages/airflow/models/taskinstance.py", line 1329, in _run_raw_task
    self._execute_task_with_callbacks(context)
  File "/home/airflow/.local/lib/python3.7/site-packages/airflow/models/taskinstance.py", line 1455, in _execute_task_with_callbacks
    result = self._execute_task(context, self.task)
  File "/home/airflow/.local/lib/python3.7/site-packages/airflow/models/taskinstance.py", line 1511, in _execute_task
    result = execute_callable(context=context)
  File "/home/airflow/.local/lib/python3.7/site-packages/airflow/operators/bash.py", line 188, in execute
    f'Bash command failed. The command returned a non-zero exit code {result.exit_code}.'
airflow.exceptions.AirflowException: Bash command failed. The command returned a non-zero exit code 1.
[2022-03-26 10:24:22,907] {taskinstance.py:1277} INFO - Marking task as UP_FOR_RETRY. dag_id=dtc_project_ingest, task_id=rm_task, execution_date=20200202T060000, start_date=20220326T102422, end_date=20220326T102422
[2022-03-26 10:24:22,923] {standard_task_runner.py:92} ERROR - Failed to execute job 1283 for task rm_task
Traceback (most recent call last):
  File "/home/airflow/.local/lib/python3.7/site-packages/airflow/task/task_runner/standard_task_runner.py", line 85, in _start_by_fork
    args.func(args, dag=self.dag)
  File "/home/airflow/.local/lib/python3.7/site-packages/airflow/cli/cli_parser.py", line 48, in command
    return func(*args, **kwargs)
  File "/home/airflow/.local/lib/python3.7/site-packages/airflow/utils/cli.py", line 92, in wrapper
    return f(*args, **kwargs)
  File "/home/airflow/.local/lib/python3.7/site-packages/airflow/cli/commands/task_command.py", line 298, in task_run
    _run_task_by_selected_method(args, dag, ti)
  File "/home/airflow/.local/lib/python3.7/site-packages/airflow/cli/commands/task_command.py", line 107, in _run_task_by_selected_method
    _run_raw_task(args, ti)
  File "/home/airflow/.local/lib/python3.7/site-packages/airflow/cli/commands/task_command.py", line 184, in _run_raw_task
    error_file=args.error_file,
  File "/home/airflow/.local/lib/python3.7/site-packages/airflow/utils/session.py", line 70, in wrapper
    return func(*args, session=session, **kwargs)
  File "/home/airflow/.local/lib/python3.7/site-packages/airflow/models/taskinstance.py", line 1329, in _run_raw_task
    self._execute_task_with_callbacks(context)
  File "/home/airflow/.local/lib/python3.7/site-packages/airflow/models/taskinstance.py", line 1455, in _execute_task_with_callbacks
    result = self._execute_task(context, self.task)
  File "/home/airflow/.local/lib/python3.7/site-packages/airflow/models/taskinstance.py", line 1511, in _execute_task
    result = execute_callable(context=context)
  File "/home/airflow/.local/lib/python3.7/site-packages/airflow/operators/bash.py", line 188, in execute
    f'Bash command failed. The command returned a non-zero exit code {result.exit_code}.'
airflow.exceptions.AirflowException: Bash command failed. The command returned a non-zero exit code 1.
[2022-03-26 10:24:22,967] {local_task_job.py:154} INFO - Task exited with return code 1
[2022-03-26 10:24:23,005] {local_task_job.py:264} INFO - 0 downstream tasks scheduled from follow-on schedule check
