[2022-03-23 09:27:46,050] {taskinstance.py:1032} INFO - Dependencies all met for <TaskInstance: dtc_project_ingest.local_to_gcs_task scheduled__2020-08-02T06:00:00+00:00 [queued]>
[2022-03-23 09:27:46,063] {taskinstance.py:1032} INFO - Dependencies all met for <TaskInstance: dtc_project_ingest.local_to_gcs_task scheduled__2020-08-02T06:00:00+00:00 [queued]>
[2022-03-23 09:27:46,064] {taskinstance.py:1238} INFO - 
--------------------------------------------------------------------------------
[2022-03-23 09:27:46,065] {taskinstance.py:1239} INFO - Starting attempt 1 of 2
[2022-03-23 09:27:46,065] {taskinstance.py:1240} INFO - 
--------------------------------------------------------------------------------
[2022-03-23 09:27:46,079] {taskinstance.py:1259} INFO - Executing <Task(PythonOperator): local_to_gcs_task> on 2020-08-02 06:00:00+00:00
[2022-03-23 09:27:46,088] {standard_task_runner.py:52} INFO - Started process 2603 to run task
[2022-03-23 09:27:46,093] {standard_task_runner.py:76} INFO - Running: ['***', 'tasks', 'run', 'dtc_project_ingest', 'local_to_gcs_task', 'scheduled__2020-08-02T06:00:00+00:00', '--job-id', '772', '--raw', '--subdir', 'DAGS_FOLDER/project_data_ingestion.py', '--cfg-path', '/tmp/tmpvw6r2w9y', '--error-file', '/tmp/tmpbpdhwt6v']
[2022-03-23 09:27:46,094] {standard_task_runner.py:77} INFO - Job 772: Subtask local_to_gcs_task
[2022-03-23 09:27:46,160] {logging_mixin.py:109} INFO - Running <TaskInstance: dtc_project_ingest.local_to_gcs_task scheduled__2020-08-02T06:00:00+00:00 [running]> on host 7127e26385ba
[2022-03-23 09:27:46,200] {warnings.py:110} WARNING - /home/***/.local/lib/python3.7/site-packages/***/utils/context.py:152: AirflowContextDeprecationWarning: Accessing 'execution_date' from the template is deprecated and will be removed in a future version. Please use 'data_interval_start' or 'logical_date' instead.
  warnings.warn(_create_deprecation_warning(key, self._deprecation_replacements[key]))

[2022-03-23 09:27:46,223] {taskinstance.py:1426} INFO - Exporting the following env vars:
AIRFLOW_CTX_DAG_OWNER=***
AIRFLOW_CTX_DAG_ID=dtc_project_ingest
AIRFLOW_CTX_TASK_ID=local_to_gcs_task
AIRFLOW_CTX_EXECUTION_DATE=2020-08-02T06:00:00+00:00
AIRFLOW_CTX_DAG_RUN_ID=scheduled__2020-08-02T06:00:00+00:00
[2022-03-23 09:28:25,636] {python.py:175} INFO - Done. Returned value was: None
[2022-03-23 09:28:25,649] {taskinstance.py:1277} INFO - Marking task as SUCCESS. dag_id=dtc_project_ingest, task_id=local_to_gcs_task, execution_date=20200802T060000, start_date=20220323T092746, end_date=20220323T092825
[2022-03-23 09:28:25,692] {local_task_job.py:154} INFO - Task exited with return code 0
[2022-03-23 09:28:25,729] {local_task_job.py:264} INFO - 1 downstream tasks scheduled from follow-on schedule check
[2022-03-23 16:36:04,987] {taskinstance.py:1032} INFO - Dependencies all met for <TaskInstance: dtc_project_ingest.local_to_gcs_task scheduled__2020-08-02T06:00:00+00:00 [queued]>
[2022-03-23 16:36:05,007] {taskinstance.py:1032} INFO - Dependencies all met for <TaskInstance: dtc_project_ingest.local_to_gcs_task scheduled__2020-08-02T06:00:00+00:00 [queued]>
[2022-03-23 16:36:05,008] {taskinstance.py:1238} INFO - 
--------------------------------------------------------------------------------
[2022-03-23 16:36:05,009] {taskinstance.py:1239} INFO - Starting attempt 1 of 2
[2022-03-23 16:36:05,011] {taskinstance.py:1240} INFO - 
--------------------------------------------------------------------------------
[2022-03-23 16:36:05,031] {taskinstance.py:1259} INFO - Executing <Task(PythonOperator): local_to_gcs_task> on 2020-08-02 06:00:00+00:00
[2022-03-23 16:36:05,042] {standard_task_runner.py:52} INFO - Started process 5960 to run task
[2022-03-23 16:36:05,048] {standard_task_runner.py:76} INFO - Running: ['***', 'tasks', 'run', 'dtc_project_ingest', 'local_to_gcs_task', 'scheduled__2020-08-02T06:00:00+00:00', '--job-id', '1089', '--raw', '--subdir', 'DAGS_FOLDER/project_data_ingestion.py', '--cfg-path', '/tmp/tmpupnrz8dl', '--error-file', '/tmp/tmpt6lc5ljs']
[2022-03-23 16:36:05,050] {standard_task_runner.py:77} INFO - Job 1089: Subtask local_to_gcs_task
[2022-03-23 16:36:05,141] {logging_mixin.py:109} INFO - Running <TaskInstance: dtc_project_ingest.local_to_gcs_task scheduled__2020-08-02T06:00:00+00:00 [running]> on host 7127e26385ba
[2022-03-23 16:36:05,200] {warnings.py:110} WARNING - /home/***/.local/lib/python3.7/site-packages/***/utils/context.py:152: AirflowContextDeprecationWarning: Accessing 'execution_date' from the template is deprecated and will be removed in a future version. Please use 'data_interval_start' or 'logical_date' instead.
  warnings.warn(_create_deprecation_warning(key, self._deprecation_replacements[key]))

[2022-03-23 16:36:05,239] {taskinstance.py:1426} INFO - Exporting the following env vars:
AIRFLOW_CTX_DAG_OWNER=***
AIRFLOW_CTX_DAG_ID=dtc_project_ingest
AIRFLOW_CTX_TASK_ID=local_to_gcs_task
AIRFLOW_CTX_EXECUTION_DATE=2020-08-02T06:00:00+00:00
AIRFLOW_CTX_DAG_RUN_ID=scheduled__2020-08-02T06:00:00+00:00
[2022-03-23 16:37:06,241] {taskinstance.py:1700} ERROR - Task failed with exception
Traceback (most recent call last):
  File "/home/airflow/.local/lib/python3.7/site-packages/urllib3/connectionpool.py", line 706, in urlopen
    chunked=chunked,
  File "/home/airflow/.local/lib/python3.7/site-packages/urllib3/connectionpool.py", line 394, in _make_request
    conn.request(method, url, **httplib_request_kw)
  File "/home/airflow/.local/lib/python3.7/site-packages/urllib3/connection.py", line 239, in request
    super(HTTPConnection, self).request(method, url, body=body, headers=headers)
  File "/usr/local/lib/python3.7/http/client.py", line 1281, in request
    self._send_request(method, url, body, headers, encode_chunked)
  File "/usr/local/lib/python3.7/http/client.py", line 1327, in _send_request
    self.endheaders(body, encode_chunked=encode_chunked)
  File "/usr/local/lib/python3.7/http/client.py", line 1276, in endheaders
    self._send_output(message_body, encode_chunked=encode_chunked)
  File "/usr/local/lib/python3.7/http/client.py", line 1075, in _send_output
    self.send(chunk)
  File "/usr/local/lib/python3.7/http/client.py", line 997, in send
    self.sock.sendall(data)
  File "/usr/local/lib/python3.7/ssl.py", line 1034, in sendall
    v = self.send(byte_view[count:])
  File "/usr/local/lib/python3.7/ssl.py", line 1003, in send
    return self._sslobj.write(data)
socket.timeout: The write operation timed out

During handling of the above exception, another exception occurred:

Traceback (most recent call last):
  File "/home/airflow/.local/lib/python3.7/site-packages/requests/adapters.py", line 449, in send
    timeout=timeout
  File "/home/airflow/.local/lib/python3.7/site-packages/urllib3/connectionpool.py", line 756, in urlopen
    method, url, error=e, _pool=self, _stacktrace=sys.exc_info()[2]
  File "/home/airflow/.local/lib/python3.7/site-packages/urllib3/util/retry.py", line 532, in increment
    raise six.reraise(type(error), error, _stacktrace)
  File "/home/airflow/.local/lib/python3.7/site-packages/urllib3/packages/six.py", line 769, in reraise
    raise value.with_traceback(tb)
  File "/home/airflow/.local/lib/python3.7/site-packages/urllib3/connectionpool.py", line 706, in urlopen
    chunked=chunked,
  File "/home/airflow/.local/lib/python3.7/site-packages/urllib3/connectionpool.py", line 394, in _make_request
    conn.request(method, url, **httplib_request_kw)
  File "/home/airflow/.local/lib/python3.7/site-packages/urllib3/connection.py", line 239, in request
    super(HTTPConnection, self).request(method, url, body=body, headers=headers)
  File "/usr/local/lib/python3.7/http/client.py", line 1281, in request
    self._send_request(method, url, body, headers, encode_chunked)
  File "/usr/local/lib/python3.7/http/client.py", line 1327, in _send_request
    self.endheaders(body, encode_chunked=encode_chunked)
  File "/usr/local/lib/python3.7/http/client.py", line 1276, in endheaders
    self._send_output(message_body, encode_chunked=encode_chunked)
  File "/usr/local/lib/python3.7/http/client.py", line 1075, in _send_output
    self.send(chunk)
  File "/usr/local/lib/python3.7/http/client.py", line 997, in send
    self.sock.sendall(data)
  File "/usr/local/lib/python3.7/ssl.py", line 1034, in sendall
    v = self.send(byte_view[count:])
  File "/usr/local/lib/python3.7/ssl.py", line 1003, in send
    return self._sslobj.write(data)
urllib3.exceptions.ProtocolError: ('Connection aborted.', timeout('The write operation timed out'))

During handling of the above exception, another exception occurred:

Traceback (most recent call last):
  File "/home/airflow/.local/lib/python3.7/site-packages/airflow/models/taskinstance.py", line 1329, in _run_raw_task
    self._execute_task_with_callbacks(context)
  File "/home/airflow/.local/lib/python3.7/site-packages/airflow/models/taskinstance.py", line 1455, in _execute_task_with_callbacks
    result = self._execute_task(context, self.task)
  File "/home/airflow/.local/lib/python3.7/site-packages/airflow/models/taskinstance.py", line 1511, in _execute_task
    result = execute_callable(context=context)
  File "/home/airflow/.local/lib/python3.7/site-packages/airflow/operators/python.py", line 174, in execute
    return_value = self.execute_callable()
  File "/home/airflow/.local/lib/python3.7/site-packages/airflow/operators/python.py", line 185, in execute_callable
    return self.python_callable(*self.op_args, **self.op_kwargs)
  File "/opt/airflow/dags/project_data_ingestion.py", line 60, in upload_to_gcs
    blob.upload_from_filename(local_file)
  File "/home/airflow/.local/lib/python3.7/site-packages/google/cloud/storage/blob.py", line 2735, in upload_from_filename
    retry=retry,
  File "/home/airflow/.local/lib/python3.7/site-packages/google/cloud/storage/blob.py", line 2594, in upload_from_file
    retry=retry,
  File "/home/airflow/.local/lib/python3.7/site-packages/google/cloud/storage/blob.py", line 2412, in _do_upload
    retry=retry,
  File "/home/airflow/.local/lib/python3.7/site-packages/google/cloud/storage/blob.py", line 2242, in _do_resumable_upload
    response = upload.transmit_next_chunk(transport, timeout=timeout)
  File "/home/airflow/.local/lib/python3.7/site-packages/google/resumable_media/requests/upload.py", line 516, in transmit_next_chunk
    retriable_request, self._get_status_code, self._retry_strategy
  File "/home/airflow/.local/lib/python3.7/site-packages/google/resumable_media/requests/_request_helpers.py", line 170, in wait_and_retry
    raise error
  File "/home/airflow/.local/lib/python3.7/site-packages/google/resumable_media/requests/_request_helpers.py", line 147, in wait_and_retry
    response = func()
  File "/home/airflow/.local/lib/python3.7/site-packages/google/resumable_media/requests/upload.py", line 508, in retriable_request
    method, url, data=payload, headers=headers, timeout=timeout
  File "/home/airflow/.local/lib/python3.7/site-packages/google/auth/transport/requests.py", line 486, in request
    **kwargs
  File "/home/airflow/.local/lib/python3.7/site-packages/requests/sessions.py", line 542, in request
    resp = self.send(prep, **send_kwargs)
  File "/home/airflow/.local/lib/python3.7/site-packages/requests/sessions.py", line 655, in send
    r = adapter.send(request, **kwargs)
  File "/home/airflow/.local/lib/python3.7/site-packages/requests/adapters.py", line 498, in send
    raise ConnectionError(err, request=request)
requests.exceptions.ConnectionError: ('Connection aborted.', timeout('The write operation timed out'))
[2022-03-23 16:37:06,334] {taskinstance.py:1277} INFO - Marking task as UP_FOR_RETRY. dag_id=dtc_project_ingest, task_id=local_to_gcs_task, execution_date=20200802T060000, start_date=20220323T163604, end_date=20220323T163706
[2022-03-23 16:37:06,408] {standard_task_runner.py:92} ERROR - Failed to execute job 1089 for task local_to_gcs_task
Traceback (most recent call last):
  File "/home/airflow/.local/lib/python3.7/site-packages/urllib3/connectionpool.py", line 706, in urlopen
    chunked=chunked,
  File "/home/airflow/.local/lib/python3.7/site-packages/urllib3/connectionpool.py", line 394, in _make_request
    conn.request(method, url, **httplib_request_kw)
  File "/home/airflow/.local/lib/python3.7/site-packages/urllib3/connection.py", line 239, in request
    super(HTTPConnection, self).request(method, url, body=body, headers=headers)
  File "/usr/local/lib/python3.7/http/client.py", line 1281, in request
    self._send_request(method, url, body, headers, encode_chunked)
  File "/usr/local/lib/python3.7/http/client.py", line 1327, in _send_request
    self.endheaders(body, encode_chunked=encode_chunked)
  File "/usr/local/lib/python3.7/http/client.py", line 1276, in endheaders
    self._send_output(message_body, encode_chunked=encode_chunked)
  File "/usr/local/lib/python3.7/http/client.py", line 1075, in _send_output
    self.send(chunk)
  File "/usr/local/lib/python3.7/http/client.py", line 997, in send
    self.sock.sendall(data)
  File "/usr/local/lib/python3.7/ssl.py", line 1034, in sendall
    v = self.send(byte_view[count:])
  File "/usr/local/lib/python3.7/ssl.py", line 1003, in send
    return self._sslobj.write(data)
socket.timeout: The write operation timed out

During handling of the above exception, another exception occurred:

Traceback (most recent call last):
  File "/home/airflow/.local/lib/python3.7/site-packages/requests/adapters.py", line 449, in send
    timeout=timeout
  File "/home/airflow/.local/lib/python3.7/site-packages/urllib3/connectionpool.py", line 756, in urlopen
    method, url, error=e, _pool=self, _stacktrace=sys.exc_info()[2]
  File "/home/airflow/.local/lib/python3.7/site-packages/urllib3/util/retry.py", line 532, in increment
    raise six.reraise(type(error), error, _stacktrace)
  File "/home/airflow/.local/lib/python3.7/site-packages/urllib3/packages/six.py", line 769, in reraise
    raise value.with_traceback(tb)
  File "/home/airflow/.local/lib/python3.7/site-packages/urllib3/connectionpool.py", line 706, in urlopen
    chunked=chunked,
  File "/home/airflow/.local/lib/python3.7/site-packages/urllib3/connectionpool.py", line 394, in _make_request
    conn.request(method, url, **httplib_request_kw)
  File "/home/airflow/.local/lib/python3.7/site-packages/urllib3/connection.py", line 239, in request
    super(HTTPConnection, self).request(method, url, body=body, headers=headers)
  File "/usr/local/lib/python3.7/http/client.py", line 1281, in request
    self._send_request(method, url, body, headers, encode_chunked)
  File "/usr/local/lib/python3.7/http/client.py", line 1327, in _send_request
    self.endheaders(body, encode_chunked=encode_chunked)
  File "/usr/local/lib/python3.7/http/client.py", line 1276, in endheaders
    self._send_output(message_body, encode_chunked=encode_chunked)
  File "/usr/local/lib/python3.7/http/client.py", line 1075, in _send_output
    self.send(chunk)
  File "/usr/local/lib/python3.7/http/client.py", line 997, in send
    self.sock.sendall(data)
  File "/usr/local/lib/python3.7/ssl.py", line 1034, in sendall
    v = self.send(byte_view[count:])
  File "/usr/local/lib/python3.7/ssl.py", line 1003, in send
    return self._sslobj.write(data)
urllib3.exceptions.ProtocolError: ('Connection aborted.', timeout('The write operation timed out'))

During handling of the above exception, another exception occurred:

Traceback (most recent call last):
  File "/home/airflow/.local/lib/python3.7/site-packages/airflow/task/task_runner/standard_task_runner.py", line 85, in _start_by_fork
    args.func(args, dag=self.dag)
  File "/home/airflow/.local/lib/python3.7/site-packages/airflow/cli/cli_parser.py", line 48, in command
    return func(*args, **kwargs)
  File "/home/airflow/.local/lib/python3.7/site-packages/airflow/utils/cli.py", line 92, in wrapper
    return f(*args, **kwargs)
  File "/home/airflow/.local/lib/python3.7/site-packages/airflow/cli/commands/task_command.py", line 298, in task_run
    _run_task_by_selected_method(args, dag, ti)
  File "/home/airflow/.local/lib/python3.7/site-packages/airflow/cli/commands/task_command.py", line 107, in _run_task_by_selected_method
    _run_raw_task(args, ti)
  File "/home/airflow/.local/lib/python3.7/site-packages/airflow/cli/commands/task_command.py", line 184, in _run_raw_task
    error_file=args.error_file,
  File "/home/airflow/.local/lib/python3.7/site-packages/airflow/utils/session.py", line 70, in wrapper
    return func(*args, session=session, **kwargs)
  File "/home/airflow/.local/lib/python3.7/site-packages/airflow/models/taskinstance.py", line 1329, in _run_raw_task
    self._execute_task_with_callbacks(context)
  File "/home/airflow/.local/lib/python3.7/site-packages/airflow/models/taskinstance.py", line 1455, in _execute_task_with_callbacks
    result = self._execute_task(context, self.task)
  File "/home/airflow/.local/lib/python3.7/site-packages/airflow/models/taskinstance.py", line 1511, in _execute_task
    result = execute_callable(context=context)
  File "/home/airflow/.local/lib/python3.7/site-packages/airflow/operators/python.py", line 174, in execute
    return_value = self.execute_callable()
  File "/home/airflow/.local/lib/python3.7/site-packages/airflow/operators/python.py", line 185, in execute_callable
    return self.python_callable(*self.op_args, **self.op_kwargs)
  File "/opt/airflow/dags/project_data_ingestion.py", line 60, in upload_to_gcs
    blob.upload_from_filename(local_file)
  File "/home/airflow/.local/lib/python3.7/site-packages/google/cloud/storage/blob.py", line 2735, in upload_from_filename
    retry=retry,
  File "/home/airflow/.local/lib/python3.7/site-packages/google/cloud/storage/blob.py", line 2594, in upload_from_file
    retry=retry,
  File "/home/airflow/.local/lib/python3.7/site-packages/google/cloud/storage/blob.py", line 2412, in _do_upload
    retry=retry,
  File "/home/airflow/.local/lib/python3.7/site-packages/google/cloud/storage/blob.py", line 2242, in _do_resumable_upload
    response = upload.transmit_next_chunk(transport, timeout=timeout)
  File "/home/airflow/.local/lib/python3.7/site-packages/google/resumable_media/requests/upload.py", line 516, in transmit_next_chunk
    retriable_request, self._get_status_code, self._retry_strategy
  File "/home/airflow/.local/lib/python3.7/site-packages/google/resumable_media/requests/_request_helpers.py", line 170, in wait_and_retry
    raise error
  File "/home/airflow/.local/lib/python3.7/site-packages/google/resumable_media/requests/_request_helpers.py", line 147, in wait_and_retry
    response = func()
  File "/home/airflow/.local/lib/python3.7/site-packages/google/resumable_media/requests/upload.py", line 508, in retriable_request
    method, url, data=payload, headers=headers, timeout=timeout
  File "/home/airflow/.local/lib/python3.7/site-packages/google/auth/transport/requests.py", line 486, in request
    **kwargs
  File "/home/airflow/.local/lib/python3.7/site-packages/requests/sessions.py", line 542, in request
    resp = self.send(prep, **send_kwargs)
  File "/home/airflow/.local/lib/python3.7/site-packages/requests/sessions.py", line 655, in send
    r = adapter.send(request, **kwargs)
  File "/home/airflow/.local/lib/python3.7/site-packages/requests/adapters.py", line 498, in send
    raise ConnectionError(err, request=request)
requests.exceptions.ConnectionError: ('Connection aborted.', timeout('The write operation timed out'))
[2022-03-23 16:37:06,466] {local_task_job.py:154} INFO - Task exited with return code 1
[2022-03-23 16:37:06,583] {local_task_job.py:264} INFO - 0 downstream tasks scheduled from follow-on schedule check
[2022-03-26 11:27:33,927] {taskinstance.py:1032} INFO - Dependencies all met for <TaskInstance: dtc_project_ingest.local_to_gcs_task scheduled__2020-08-02T06:00:00+00:00 [queued]>
[2022-03-26 11:27:33,953] {taskinstance.py:1032} INFO - Dependencies all met for <TaskInstance: dtc_project_ingest.local_to_gcs_task scheduled__2020-08-02T06:00:00+00:00 [queued]>
[2022-03-26 11:27:33,955] {taskinstance.py:1238} INFO - 
--------------------------------------------------------------------------------
[2022-03-26 11:27:33,956] {taskinstance.py:1239} INFO - Starting attempt 1 of 2
[2022-03-26 11:27:33,957] {taskinstance.py:1240} INFO - 
--------------------------------------------------------------------------------
[2022-03-26 11:27:33,990] {taskinstance.py:1259} INFO - Executing <Task(PythonOperator): local_to_gcs_task> on 2020-08-02 06:00:00+00:00
[2022-03-26 11:27:34,009] {standard_task_runner.py:52} INFO - Started process 8228 to run task
[2022-03-26 11:27:34,033] {standard_task_runner.py:76} INFO - Running: ['***', 'tasks', 'run', 'dtc_project_ingest', 'local_to_gcs_task', 'scheduled__2020-08-02T06:00:00+00:00', '--job-id', '1447', '--raw', '--subdir', 'DAGS_FOLDER/project_data_ingestion.py', '--cfg-path', '/tmp/tmp2wpxv52b', '--error-file', '/tmp/tmp6zgh1jga']
[2022-03-26 11:27:34,036] {standard_task_runner.py:77} INFO - Job 1447: Subtask local_to_gcs_task
[2022-03-26 11:27:34,193] {logging_mixin.py:109} INFO - Running <TaskInstance: dtc_project_ingest.local_to_gcs_task scheduled__2020-08-02T06:00:00+00:00 [running]> on host c800f4dda314
[2022-03-26 11:27:34,273] {warnings.py:110} WARNING - /home/***/.local/lib/python3.7/site-packages/***/utils/context.py:152: AirflowContextDeprecationWarning: Accessing 'execution_date' from the template is deprecated and will be removed in a future version. Please use 'data_interval_start' or 'logical_date' instead.
  warnings.warn(_create_deprecation_warning(key, self._deprecation_replacements[key]))

[2022-03-26 11:27:34,310] {taskinstance.py:1426} INFO - Exporting the following env vars:
AIRFLOW_CTX_DAG_OWNER=***
AIRFLOW_CTX_DAG_ID=dtc_project_ingest
AIRFLOW_CTX_TASK_ID=local_to_gcs_task
AIRFLOW_CTX_EXECUTION_DATE=2020-08-02T06:00:00+00:00
AIRFLOW_CTX_DAG_RUN_ID=scheduled__2020-08-02T06:00:00+00:00
[2022-03-26 11:30:35,288] {python.py:175} INFO - Done. Returned value was: None
[2022-03-26 11:30:35,303] {taskinstance.py:1277} INFO - Marking task as SUCCESS. dag_id=dtc_project_ingest, task_id=local_to_gcs_task, execution_date=20200802T060000, start_date=20220326T112733, end_date=20220326T113035
[2022-03-26 11:30:35,334] {local_task_job.py:154} INFO - Task exited with return code 0
[2022-03-26 11:30:35,378] {local_task_job.py:264} INFO - 1 downstream tasks scheduled from follow-on schedule check
[2022-03-26 15:47:22,690] {taskinstance.py:1032} INFO - Dependencies all met for <TaskInstance: dtc_project_ingest.local_to_gcs_task scheduled__2020-08-02T06:00:00+00:00 [queued]>
[2022-03-26 15:47:22,706] {taskinstance.py:1032} INFO - Dependencies all met for <TaskInstance: dtc_project_ingest.local_to_gcs_task scheduled__2020-08-02T06:00:00+00:00 [queued]>
[2022-03-26 15:47:22,707] {taskinstance.py:1238} INFO - 
--------------------------------------------------------------------------------
[2022-03-26 15:47:22,709] {taskinstance.py:1239} INFO - Starting attempt 1 of 2
[2022-03-26 15:47:22,710] {taskinstance.py:1240} INFO - 
--------------------------------------------------------------------------------
[2022-03-26 15:47:22,726] {taskinstance.py:1259} INFO - Executing <Task(PythonOperator): local_to_gcs_task> on 2020-08-02 06:00:00+00:00
[2022-03-26 15:47:22,736] {standard_task_runner.py:52} INFO - Started process 21307 to run task
[2022-03-26 15:47:22,744] {standard_task_runner.py:76} INFO - Running: ['***', 'tasks', 'run', 'dtc_project_ingest', 'local_to_gcs_task', 'scheduled__2020-08-02T06:00:00+00:00', '--job-id', '1671', '--raw', '--subdir', 'DAGS_FOLDER/project_data_ingestion.py', '--cfg-path', '/tmp/tmp0tyuasvn', '--error-file', '/tmp/tmpio243j90']
[2022-03-26 15:47:22,747] {standard_task_runner.py:77} INFO - Job 1671: Subtask local_to_gcs_task
[2022-03-26 15:47:22,847] {logging_mixin.py:109} INFO - Running <TaskInstance: dtc_project_ingest.local_to_gcs_task scheduled__2020-08-02T06:00:00+00:00 [running]> on host c800f4dda314
[2022-03-26 15:47:22,904] {warnings.py:110} WARNING - /home/***/.local/lib/python3.7/site-packages/***/utils/context.py:152: AirflowContextDeprecationWarning: Accessing 'execution_date' from the template is deprecated and will be removed in a future version. Please use 'data_interval_start' or 'logical_date' instead.
  warnings.warn(_create_deprecation_warning(key, self._deprecation_replacements[key]))

[2022-03-26 15:47:22,940] {taskinstance.py:1426} INFO - Exporting the following env vars:
AIRFLOW_CTX_DAG_OWNER=***
AIRFLOW_CTX_DAG_ID=dtc_project_ingest
AIRFLOW_CTX_TASK_ID=local_to_gcs_task
AIRFLOW_CTX_EXECUTION_DATE=2020-08-02T06:00:00+00:00
AIRFLOW_CTX_DAG_RUN_ID=scheduled__2020-08-02T06:00:00+00:00
[2022-03-26 15:48:58,620] {python.py:175} INFO - Done. Returned value was: None
[2022-03-26 15:48:58,647] {taskinstance.py:1277} INFO - Marking task as SUCCESS. dag_id=dtc_project_ingest, task_id=local_to_gcs_task, execution_date=20200802T060000, start_date=20220326T154722, end_date=20220326T154858
[2022-03-26 15:48:58,732] {local_task_job.py:154} INFO - Task exited with return code 0
[2022-03-26 15:48:58,832] {local_task_job.py:264} INFO - 1 downstream tasks scheduled from follow-on schedule check
