[2022-03-23 15:20:23,169] {taskinstance.py:1032} INFO - Dependencies all met for <TaskInstance: dtc_project_ingest.bigquery_external_table_task scheduled__2018-04-02T06:00:00+00:00 [queued]>
[2022-03-23 15:20:23,182] {taskinstance.py:1032} INFO - Dependencies all met for <TaskInstance: dtc_project_ingest.bigquery_external_table_task scheduled__2018-04-02T06:00:00+00:00 [queued]>
[2022-03-23 15:20:23,184] {taskinstance.py:1238} INFO - 
--------------------------------------------------------------------------------
[2022-03-23 15:20:23,184] {taskinstance.py:1239} INFO - Starting attempt 1 of 2
[2022-03-23 15:20:23,185] {taskinstance.py:1240} INFO - 
--------------------------------------------------------------------------------
[2022-03-23 15:20:23,198] {taskinstance.py:1259} INFO - Executing <Task(BigQueryCreateExternalTableOperator): bigquery_external_table_task> on 2018-04-02 06:00:00+00:00
[2022-03-23 15:20:23,205] {standard_task_runner.py:52} INFO - Started process 1583 to run task
[2022-03-23 15:20:23,210] {standard_task_runner.py:76} INFO - Running: ['***', 'tasks', 'run', 'dtc_project_ingest', 'bigquery_external_table_task', 'scheduled__2018-04-02T06:00:00+00:00', '--job-id', '881', '--raw', '--subdir', 'DAGS_FOLDER/project_data_ingestion.py', '--cfg-path', '/tmp/tmpnfcy9ypz', '--error-file', '/tmp/tmps2gfabhi']
[2022-03-23 15:20:23,212] {standard_task_runner.py:77} INFO - Job 881: Subtask bigquery_external_table_task
[2022-03-23 15:20:23,289] {logging_mixin.py:109} INFO - Running <TaskInstance: dtc_project_ingest.bigquery_external_table_task scheduled__2018-04-02T06:00:00+00:00 [running]> on host 7127e26385ba
[2022-03-23 15:20:23,337] {warnings.py:110} WARNING - /home/***/.local/lib/python3.7/site-packages/***/utils/context.py:152: AirflowContextDeprecationWarning: Accessing 'execution_date' from the template is deprecated and will be removed in a future version. Please use 'data_interval_start' or 'logical_date' instead.
  warnings.warn(_create_deprecation_warning(key, self._deprecation_replacements[key]))

[2022-03-23 15:20:23,368] {taskinstance.py:1426} INFO - Exporting the following env vars:
AIRFLOW_CTX_DAG_OWNER=***
AIRFLOW_CTX_DAG_ID=dtc_project_ingest
AIRFLOW_CTX_TASK_ID=bigquery_external_table_task
AIRFLOW_CTX_EXECUTION_DATE=2018-04-02T06:00:00+00:00
AIRFLOW_CTX_DAG_RUN_ID=scheduled__2018-04-02T06:00:00+00:00
[2022-03-23 15:20:23,371] {crypto.py:82} WARNING - empty cryptography key - values will not be stored encrypted.
[2022-03-23 15:20:24,686] {taskinstance.py:1700} ERROR - Task failed with exception
Traceback (most recent call last):
  File "/home/airflow/.local/lib/python3.7/site-packages/airflow/models/taskinstance.py", line 1329, in _run_raw_task
    self._execute_task_with_callbacks(context)
  File "/home/airflow/.local/lib/python3.7/site-packages/airflow/models/taskinstance.py", line 1455, in _execute_task_with_callbacks
    result = self._execute_task(context, self.task)
  File "/home/airflow/.local/lib/python3.7/site-packages/airflow/models/taskinstance.py", line 1511, in _execute_task
    result = execute_callable(context=context)
  File "/home/airflow/.local/lib/python3.7/site-packages/airflow/providers/google/cloud/operators/bigquery.py", line 1196, in execute
    table_resource=self.table_resource,
  File "/home/airflow/.local/lib/python3.7/site-packages/airflow/providers/google/common/hooks/base_google.py", line 430, in inner_wrapper
    return func(self, *args, **kwargs)
  File "/home/airflow/.local/lib/python3.7/site-packages/airflow/providers/google/cloud/hooks/bigquery.py", line 408, in create_empty_table
    table=table, exists_ok=exists_ok, retry=retry
  File "/home/airflow/.local/lib/python3.7/site-packages/google/cloud/bigquery/client.py", line 755, in create_table
    timeout=timeout,
  File "/home/airflow/.local/lib/python3.7/site-packages/google/cloud/bigquery/client.py", line 782, in _call_api
    return call()
  File "/home/airflow/.local/lib/python3.7/site-packages/google/api_core/retry.py", line 291, in retry_wrapped_func
    on_error=on_error,
  File "/home/airflow/.local/lib/python3.7/site-packages/google/api_core/retry.py", line 189, in retry_target
    return target()
  File "/home/airflow/.local/lib/python3.7/site-packages/google/cloud/_http.py", line 484, in api_request
    raise exceptions.from_http_response(response)
google.api_core.exceptions.BadRequest: 400 POST https://bigquery.googleapis.com/bigquery/v2/projects/healthy-fuze-339218/datasets/citibike_project/tables?prettyPrint=false: Error while reading table: citibike_project, error message: Failed to expand table citibike_project with file pattern gs://dtc_citibike_project/raw//opt/airflow/201804-citibike-tripdata.parquet: matched no files.
[2022-03-23 15:20:24,707] {taskinstance.py:1277} INFO - Marking task as UP_FOR_RETRY. dag_id=dtc_project_ingest, task_id=bigquery_external_table_task, execution_date=20180402T060000, start_date=20220323T152023, end_date=20220323T152024
[2022-03-23 15:20:24,723] {standard_task_runner.py:92} ERROR - Failed to execute job 881 for task bigquery_external_table_task
Traceback (most recent call last):
  File "/home/airflow/.local/lib/python3.7/site-packages/airflow/task/task_runner/standard_task_runner.py", line 85, in _start_by_fork
    args.func(args, dag=self.dag)
  File "/home/airflow/.local/lib/python3.7/site-packages/airflow/cli/cli_parser.py", line 48, in command
    return func(*args, **kwargs)
  File "/home/airflow/.local/lib/python3.7/site-packages/airflow/utils/cli.py", line 92, in wrapper
    return f(*args, **kwargs)
  File "/home/airflow/.local/lib/python3.7/site-packages/airflow/cli/commands/task_command.py", line 298, in task_run
    _run_task_by_selected_method(args, dag, ti)
  File "/home/airflow/.local/lib/python3.7/site-packages/airflow/cli/commands/task_command.py", line 107, in _run_task_by_selected_method
    _run_raw_task(args, ti)
  File "/home/airflow/.local/lib/python3.7/site-packages/airflow/cli/commands/task_command.py", line 184, in _run_raw_task
    error_file=args.error_file,
  File "/home/airflow/.local/lib/python3.7/site-packages/airflow/utils/session.py", line 70, in wrapper
    return func(*args, session=session, **kwargs)
  File "/home/airflow/.local/lib/python3.7/site-packages/airflow/models/taskinstance.py", line 1329, in _run_raw_task
    self._execute_task_with_callbacks(context)
  File "/home/airflow/.local/lib/python3.7/site-packages/airflow/models/taskinstance.py", line 1455, in _execute_task_with_callbacks
    result = self._execute_task(context, self.task)
  File "/home/airflow/.local/lib/python3.7/site-packages/airflow/models/taskinstance.py", line 1511, in _execute_task
    result = execute_callable(context=context)
  File "/home/airflow/.local/lib/python3.7/site-packages/airflow/providers/google/cloud/operators/bigquery.py", line 1196, in execute
    table_resource=self.table_resource,
  File "/home/airflow/.local/lib/python3.7/site-packages/airflow/providers/google/common/hooks/base_google.py", line 430, in inner_wrapper
    return func(self, *args, **kwargs)
  File "/home/airflow/.local/lib/python3.7/site-packages/airflow/providers/google/cloud/hooks/bigquery.py", line 408, in create_empty_table
    table=table, exists_ok=exists_ok, retry=retry
  File "/home/airflow/.local/lib/python3.7/site-packages/google/cloud/bigquery/client.py", line 755, in create_table
    timeout=timeout,
  File "/home/airflow/.local/lib/python3.7/site-packages/google/cloud/bigquery/client.py", line 782, in _call_api
    return call()
  File "/home/airflow/.local/lib/python3.7/site-packages/google/api_core/retry.py", line 291, in retry_wrapped_func
    on_error=on_error,
  File "/home/airflow/.local/lib/python3.7/site-packages/google/api_core/retry.py", line 189, in retry_target
    return target()
  File "/home/airflow/.local/lib/python3.7/site-packages/google/cloud/_http.py", line 484, in api_request
    raise exceptions.from_http_response(response)
google.api_core.exceptions.BadRequest: 400 POST https://bigquery.googleapis.com/bigquery/v2/projects/healthy-fuze-339218/datasets/citibike_project/tables?prettyPrint=false: Error while reading table: citibike_project, error message: Failed to expand table citibike_project with file pattern gs://dtc_citibike_project/raw//opt/airflow/201804-citibike-tripdata.parquet: matched no files.
[2022-03-23 15:20:24,756] {local_task_job.py:154} INFO - Task exited with return code 1
[2022-03-23 15:20:24,806] {local_task_job.py:264} INFO - 0 downstream tasks scheduled from follow-on schedule check
[2022-03-23 15:56:48,671] {taskinstance.py:1032} INFO - Dependencies all met for <TaskInstance: dtc_project_ingest.bigquery_external_table_task scheduled__2018-04-02T06:00:00+00:00 [queued]>
[2022-03-23 15:56:48,686] {taskinstance.py:1032} INFO - Dependencies all met for <TaskInstance: dtc_project_ingest.bigquery_external_table_task scheduled__2018-04-02T06:00:00+00:00 [queued]>
[2022-03-23 15:56:48,686] {taskinstance.py:1238} INFO - 
--------------------------------------------------------------------------------
[2022-03-23 15:56:48,687] {taskinstance.py:1239} INFO - Starting attempt 1 of 2
[2022-03-23 15:56:48,688] {taskinstance.py:1240} INFO - 
--------------------------------------------------------------------------------
[2022-03-23 15:56:48,702] {taskinstance.py:1259} INFO - Executing <Task(BigQueryCreateExternalTableOperator): bigquery_external_table_task> on 2018-04-02 06:00:00+00:00
[2022-03-23 15:56:48,723] {standard_task_runner.py:52} INFO - Started process 3468 to run task
[2022-03-23 15:56:48,729] {standard_task_runner.py:76} INFO - Running: ['***', 'tasks', 'run', 'dtc_project_ingest', 'bigquery_external_table_task', 'scheduled__2018-04-02T06:00:00+00:00', '--job-id', '952', '--raw', '--subdir', 'DAGS_FOLDER/project_data_ingestion.py', '--cfg-path', '/tmp/tmpah9bxebo', '--error-file', '/tmp/tmpwgjtqw4x']
[2022-03-23 15:56:48,730] {standard_task_runner.py:77} INFO - Job 952: Subtask bigquery_external_table_task
[2022-03-23 15:56:48,801] {logging_mixin.py:109} INFO - Running <TaskInstance: dtc_project_ingest.bigquery_external_table_task scheduled__2018-04-02T06:00:00+00:00 [running]> on host 7127e26385ba
[2022-03-23 15:56:48,855] {warnings.py:110} WARNING - /home/***/.local/lib/python3.7/site-packages/***/utils/context.py:152: AirflowContextDeprecationWarning: Accessing 'execution_date' from the template is deprecated and will be removed in a future version. Please use 'data_interval_start' or 'logical_date' instead.
  warnings.warn(_create_deprecation_warning(key, self._deprecation_replacements[key]))

[2022-03-23 15:56:48,878] {taskinstance.py:1426} INFO - Exporting the following env vars:
AIRFLOW_CTX_DAG_OWNER=***
AIRFLOW_CTX_DAG_ID=dtc_project_ingest
AIRFLOW_CTX_TASK_ID=bigquery_external_table_task
AIRFLOW_CTX_EXECUTION_DATE=2018-04-02T06:00:00+00:00
AIRFLOW_CTX_DAG_RUN_ID=scheduled__2018-04-02T06:00:00+00:00
[2022-03-23 15:56:48,880] {crypto.py:82} WARNING - empty cryptography key - values will not be stored encrypted.
[2022-03-23 15:56:49,970] {taskinstance.py:1277} INFO - Marking task as SUCCESS. dag_id=dtc_project_ingest, task_id=bigquery_external_table_task, execution_date=20180402T060000, start_date=20220323T155648, end_date=20220323T155649
[2022-03-23 15:56:50,028] {local_task_job.py:154} INFO - Task exited with return code 0
[2022-03-23 15:56:50,068] {local_task_job.py:264} INFO - 1 downstream tasks scheduled from follow-on schedule check
[2022-03-26 10:32:17,022] {taskinstance.py:1032} INFO - Dependencies all met for <TaskInstance: dtc_project_ingest.bigquery_external_table_task scheduled__2018-04-02T06:00:00+00:00 [queued]>
[2022-03-26 10:32:17,038] {taskinstance.py:1032} INFO - Dependencies all met for <TaskInstance: dtc_project_ingest.bigquery_external_table_task scheduled__2018-04-02T06:00:00+00:00 [queued]>
[2022-03-26 10:32:17,039] {taskinstance.py:1238} INFO - 
--------------------------------------------------------------------------------
[2022-03-26 10:32:17,040] {taskinstance.py:1239} INFO - Starting attempt 1 of 2
[2022-03-26 10:32:17,042] {taskinstance.py:1240} INFO - 
--------------------------------------------------------------------------------
[2022-03-26 10:32:17,061] {taskinstance.py:1259} INFO - Executing <Task(BigQueryCreateExternalTableOperator): bigquery_external_table_task> on 2018-04-02 06:00:00+00:00
[2022-03-26 10:32:17,071] {standard_task_runner.py:52} INFO - Started process 5083 to run task
[2022-03-26 10:32:17,076] {standard_task_runner.py:76} INFO - Running: ['***', 'tasks', 'run', 'dtc_project_ingest', 'bigquery_external_table_task', 'scheduled__2018-04-02T06:00:00+00:00', '--job-id', '1306', '--raw', '--subdir', 'DAGS_FOLDER/project_data_ingestion.py', '--cfg-path', '/tmp/tmp99xbp5fi', '--error-file', '/tmp/tmpeemju3ne']
[2022-03-26 10:32:17,078] {standard_task_runner.py:77} INFO - Job 1306: Subtask bigquery_external_table_task
[2022-03-26 10:32:17,171] {logging_mixin.py:109} INFO - Running <TaskInstance: dtc_project_ingest.bigquery_external_table_task scheduled__2018-04-02T06:00:00+00:00 [running]> on host c800f4dda314
[2022-03-26 10:32:17,259] {taskinstance.py:1426} INFO - Exporting the following env vars:
AIRFLOW_CTX_DAG_OWNER=***
AIRFLOW_CTX_DAG_ID=dtc_project_ingest
AIRFLOW_CTX_TASK_ID=bigquery_external_table_task
AIRFLOW_CTX_EXECUTION_DATE=2018-04-02T06:00:00+00:00
AIRFLOW_CTX_DAG_RUN_ID=scheduled__2018-04-02T06:00:00+00:00
[2022-03-26 10:32:17,262] {crypto.py:82} WARNING - empty cryptography key - values will not be stored encrypted.
[2022-03-26 10:32:20,834] {taskinstance.py:1277} INFO - Marking task as SUCCESS. dag_id=dtc_project_ingest, task_id=bigquery_external_table_task, execution_date=20180402T060000, start_date=20220326T103217, end_date=20220326T103220
[2022-03-26 10:32:20,860] {local_task_job.py:154} INFO - Task exited with return code 0
[2022-03-26 10:32:20,899] {local_task_job.py:264} INFO - 1 downstream tasks scheduled from follow-on schedule check
