[2022-03-23 15:34:40,800] {taskinstance.py:1032} INFO - Dependencies all met for <TaskInstance: dtc_project_ingest.bigquery_external_table_task scheduled__2018-11-02T06:00:00+00:00 [queued]>
[2022-03-23 15:34:40,841] {taskinstance.py:1032} INFO - Dependencies all met for <TaskInstance: dtc_project_ingest.bigquery_external_table_task scheduled__2018-11-02T06:00:00+00:00 [queued]>
[2022-03-23 15:34:40,898] {taskinstance.py:1238} INFO - 
--------------------------------------------------------------------------------
[2022-03-23 15:34:40,899] {taskinstance.py:1239} INFO - Starting attempt 1 of 2
[2022-03-23 15:34:40,901] {taskinstance.py:1240} INFO - 
--------------------------------------------------------------------------------
[2022-03-23 15:34:40,982] {taskinstance.py:1259} INFO - Executing <Task(BigQueryCreateExternalTableOperator): bigquery_external_table_task> on 2018-11-02 06:00:00+00:00
[2022-03-23 15:34:40,992] {standard_task_runner.py:52} INFO - Started process 2322 to run task
[2022-03-23 15:34:41,011] {standard_task_runner.py:76} INFO - Running: ['***', 'tasks', 'run', 'dtc_project_ingest', 'bigquery_external_table_task', 'scheduled__2018-11-02T06:00:00+00:00', '--job-id', '910', '--raw', '--subdir', 'DAGS_FOLDER/project_data_ingestion.py', '--cfg-path', '/tmp/tmpph52ii7d', '--error-file', '/tmp/tmpqmc0rx0h']
[2022-03-23 15:34:41,032] {standard_task_runner.py:77} INFO - Job 910: Subtask bigquery_external_table_task
[2022-03-23 15:34:41,228] {logging_mixin.py:109} INFO - Running <TaskInstance: dtc_project_ingest.bigquery_external_table_task scheduled__2018-11-02T06:00:00+00:00 [running]> on host 7127e26385ba
[2022-03-23 15:34:41,415] {warnings.py:110} WARNING - /home/***/.local/lib/python3.7/site-packages/***/utils/context.py:152: AirflowContextDeprecationWarning: Accessing 'execution_date' from the template is deprecated and will be removed in a future version. Please use 'data_interval_start' or 'logical_date' instead.
  warnings.warn(_create_deprecation_warning(key, self._deprecation_replacements[key]))

[2022-03-23 15:34:41,530] {taskinstance.py:1426} INFO - Exporting the following env vars:
AIRFLOW_CTX_DAG_OWNER=***
AIRFLOW_CTX_DAG_ID=dtc_project_ingest
AIRFLOW_CTX_TASK_ID=bigquery_external_table_task
AIRFLOW_CTX_EXECUTION_DATE=2018-11-02T06:00:00+00:00
AIRFLOW_CTX_DAG_RUN_ID=scheduled__2018-11-02T06:00:00+00:00
[2022-03-23 15:34:41,539] {crypto.py:82} WARNING - empty cryptography key - values will not be stored encrypted.
[2022-03-23 15:34:42,667] {taskinstance.py:1700} ERROR - Task failed with exception
Traceback (most recent call last):
  File "/home/airflow/.local/lib/python3.7/site-packages/airflow/models/taskinstance.py", line 1329, in _run_raw_task
    self._execute_task_with_callbacks(context)
  File "/home/airflow/.local/lib/python3.7/site-packages/airflow/models/taskinstance.py", line 1455, in _execute_task_with_callbacks
    result = self._execute_task(context, self.task)
  File "/home/airflow/.local/lib/python3.7/site-packages/airflow/models/taskinstance.py", line 1511, in _execute_task
    result = execute_callable(context=context)
  File "/home/airflow/.local/lib/python3.7/site-packages/airflow/providers/google/cloud/operators/bigquery.py", line 1196, in execute
    table_resource=self.table_resource,
  File "/home/airflow/.local/lib/python3.7/site-packages/airflow/providers/google/common/hooks/base_google.py", line 430, in inner_wrapper
    return func(self, *args, **kwargs)
  File "/home/airflow/.local/lib/python3.7/site-packages/airflow/providers/google/cloud/hooks/bigquery.py", line 408, in create_empty_table
    table=table, exists_ok=exists_ok, retry=retry
  File "/home/airflow/.local/lib/python3.7/site-packages/google/cloud/bigquery/client.py", line 755, in create_table
    timeout=timeout,
  File "/home/airflow/.local/lib/python3.7/site-packages/google/cloud/bigquery/client.py", line 782, in _call_api
    return call()
  File "/home/airflow/.local/lib/python3.7/site-packages/google/api_core/retry.py", line 291, in retry_wrapped_func
    on_error=on_error,
  File "/home/airflow/.local/lib/python3.7/site-packages/google/api_core/retry.py", line 189, in retry_target
    return target()
  File "/home/airflow/.local/lib/python3.7/site-packages/google/cloud/_http.py", line 484, in api_request
    raise exceptions.from_http_response(response)
google.api_core.exceptions.BadRequest: 400 POST https://bigquery.googleapis.com/bigquery/v2/projects/healthy-fuze-339218/datasets/citibike_project/tables?prettyPrint=false: Error while reading table: citibike_project, error message: Failed to expand table citibike_project with file pattern gs://dtc_citibike_project/raw//opt/airflow/201811-citibike-tripdata.parquet: matched no files.
[2022-03-23 15:34:42,720] {taskinstance.py:1277} INFO - Marking task as UP_FOR_RETRY. dag_id=dtc_project_ingest, task_id=bigquery_external_table_task, execution_date=20181102T060000, start_date=20220323T153440, end_date=20220323T153442
[2022-03-23 15:34:42,821] {standard_task_runner.py:92} ERROR - Failed to execute job 910 for task bigquery_external_table_task
Traceback (most recent call last):
  File "/home/airflow/.local/lib/python3.7/site-packages/airflow/task/task_runner/standard_task_runner.py", line 85, in _start_by_fork
    args.func(args, dag=self.dag)
  File "/home/airflow/.local/lib/python3.7/site-packages/airflow/cli/cli_parser.py", line 48, in command
    return func(*args, **kwargs)
  File "/home/airflow/.local/lib/python3.7/site-packages/airflow/utils/cli.py", line 92, in wrapper
    return f(*args, **kwargs)
  File "/home/airflow/.local/lib/python3.7/site-packages/airflow/cli/commands/task_command.py", line 298, in task_run
    _run_task_by_selected_method(args, dag, ti)
  File "/home/airflow/.local/lib/python3.7/site-packages/airflow/cli/commands/task_command.py", line 107, in _run_task_by_selected_method
    _run_raw_task(args, ti)
  File "/home/airflow/.local/lib/python3.7/site-packages/airflow/cli/commands/task_command.py", line 184, in _run_raw_task
    error_file=args.error_file,
  File "/home/airflow/.local/lib/python3.7/site-packages/airflow/utils/session.py", line 70, in wrapper
    return func(*args, session=session, **kwargs)
  File "/home/airflow/.local/lib/python3.7/site-packages/airflow/models/taskinstance.py", line 1329, in _run_raw_task
    self._execute_task_with_callbacks(context)
  File "/home/airflow/.local/lib/python3.7/site-packages/airflow/models/taskinstance.py", line 1455, in _execute_task_with_callbacks
    result = self._execute_task(context, self.task)
  File "/home/airflow/.local/lib/python3.7/site-packages/airflow/models/taskinstance.py", line 1511, in _execute_task
    result = execute_callable(context=context)
  File "/home/airflow/.local/lib/python3.7/site-packages/airflow/providers/google/cloud/operators/bigquery.py", line 1196, in execute
    table_resource=self.table_resource,
  File "/home/airflow/.local/lib/python3.7/site-packages/airflow/providers/google/common/hooks/base_google.py", line 430, in inner_wrapper
    return func(self, *args, **kwargs)
  File "/home/airflow/.local/lib/python3.7/site-packages/airflow/providers/google/cloud/hooks/bigquery.py", line 408, in create_empty_table
    table=table, exists_ok=exists_ok, retry=retry
  File "/home/airflow/.local/lib/python3.7/site-packages/google/cloud/bigquery/client.py", line 755, in create_table
    timeout=timeout,
  File "/home/airflow/.local/lib/python3.7/site-packages/google/cloud/bigquery/client.py", line 782, in _call_api
    return call()
  File "/home/airflow/.local/lib/python3.7/site-packages/google/api_core/retry.py", line 291, in retry_wrapped_func
    on_error=on_error,
  File "/home/airflow/.local/lib/python3.7/site-packages/google/api_core/retry.py", line 189, in retry_target
    return target()
  File "/home/airflow/.local/lib/python3.7/site-packages/google/cloud/_http.py", line 484, in api_request
    raise exceptions.from_http_response(response)
google.api_core.exceptions.BadRequest: 400 POST https://bigquery.googleapis.com/bigquery/v2/projects/healthy-fuze-339218/datasets/citibike_project/tables?prettyPrint=false: Error while reading table: citibike_project, error message: Failed to expand table citibike_project with file pattern gs://dtc_citibike_project/raw//opt/airflow/201811-citibike-tripdata.parquet: matched no files.
[2022-03-23 15:34:42,921] {local_task_job.py:154} INFO - Task exited with return code 1
[2022-03-23 15:34:43,077] {local_task_job.py:264} INFO - 0 downstream tasks scheduled from follow-on schedule check
[2022-03-23 16:04:00,689] {taskinstance.py:1032} INFO - Dependencies all met for <TaskInstance: dtc_project_ingest.bigquery_external_table_task scheduled__2018-11-02T06:00:00+00:00 [queued]>
[2022-03-23 16:04:00,701] {taskinstance.py:1032} INFO - Dependencies all met for <TaskInstance: dtc_project_ingest.bigquery_external_table_task scheduled__2018-11-02T06:00:00+00:00 [queued]>
[2022-03-23 16:04:00,702] {taskinstance.py:1238} INFO - 
--------------------------------------------------------------------------------
[2022-03-23 16:04:00,703] {taskinstance.py:1239} INFO - Starting attempt 1 of 2
[2022-03-23 16:04:00,703] {taskinstance.py:1240} INFO - 
--------------------------------------------------------------------------------
[2022-03-23 16:04:00,715] {taskinstance.py:1259} INFO - Executing <Task(BigQueryCreateExternalTableOperator): bigquery_external_table_task> on 2018-11-02 06:00:00+00:00
[2022-03-23 16:04:00,721] {standard_task_runner.py:52} INFO - Started process 3949 to run task
[2022-03-23 16:04:00,728] {standard_task_runner.py:76} INFO - Running: ['***', 'tasks', 'run', 'dtc_project_ingest', 'bigquery_external_table_task', 'scheduled__2018-11-02T06:00:00+00:00', '--job-id', '984', '--raw', '--subdir', 'DAGS_FOLDER/project_data_ingestion.py', '--cfg-path', '/tmp/tmpdkxedi4m', '--error-file', '/tmp/tmpimsd1ree']
[2022-03-23 16:04:00,730] {standard_task_runner.py:77} INFO - Job 984: Subtask bigquery_external_table_task
[2022-03-23 16:04:00,814] {logging_mixin.py:109} INFO - Running <TaskInstance: dtc_project_ingest.bigquery_external_table_task scheduled__2018-11-02T06:00:00+00:00 [running]> on host 7127e26385ba
[2022-03-23 16:04:00,886] {warnings.py:110} WARNING - /home/***/.local/lib/python3.7/site-packages/***/utils/context.py:152: AirflowContextDeprecationWarning: Accessing 'execution_date' from the template is deprecated and will be removed in a future version. Please use 'data_interval_start' or 'logical_date' instead.
  warnings.warn(_create_deprecation_warning(key, self._deprecation_replacements[key]))

[2022-03-23 16:04:00,909] {taskinstance.py:1426} INFO - Exporting the following env vars:
AIRFLOW_CTX_DAG_OWNER=***
AIRFLOW_CTX_DAG_ID=dtc_project_ingest
AIRFLOW_CTX_TASK_ID=bigquery_external_table_task
AIRFLOW_CTX_EXECUTION_DATE=2018-11-02T06:00:00+00:00
AIRFLOW_CTX_DAG_RUN_ID=scheduled__2018-11-02T06:00:00+00:00
[2022-03-23 16:04:00,911] {crypto.py:82} WARNING - empty cryptography key - values will not be stored encrypted.
[2022-03-23 16:04:02,214] {taskinstance.py:1277} INFO - Marking task as SUCCESS. dag_id=dtc_project_ingest, task_id=bigquery_external_table_task, execution_date=20181102T060000, start_date=20220323T160400, end_date=20220323T160402
[2022-03-23 16:04:02,271] {local_task_job.py:154} INFO - Task exited with return code 0
[2022-03-23 16:04:02,307] {local_task_job.py:264} INFO - 1 downstream tasks scheduled from follow-on schedule check
[2022-03-26 10:54:49,454] {taskinstance.py:1032} INFO - Dependencies all met for <TaskInstance: dtc_project_ingest.bigquery_external_table_task scheduled__2018-11-02T06:00:00+00:00 [queued]>
[2022-03-26 10:54:49,471] {taskinstance.py:1032} INFO - Dependencies all met for <TaskInstance: dtc_project_ingest.bigquery_external_table_task scheduled__2018-11-02T06:00:00+00:00 [queued]>
[2022-03-26 10:54:49,473] {taskinstance.py:1238} INFO - 
--------------------------------------------------------------------------------
[2022-03-26 10:54:49,474] {taskinstance.py:1239} INFO - Starting attempt 1 of 2
[2022-03-26 10:54:49,475] {taskinstance.py:1240} INFO - 
--------------------------------------------------------------------------------
[2022-03-26 10:54:49,492] {taskinstance.py:1259} INFO - Executing <Task(BigQueryCreateExternalTableOperator): bigquery_external_table_task> on 2018-11-02 06:00:00+00:00
[2022-03-26 10:54:49,503] {standard_task_runner.py:52} INFO - Started process 6296 to run task
[2022-03-26 10:54:49,509] {standard_task_runner.py:76} INFO - Running: ['***', 'tasks', 'run', 'dtc_project_ingest', 'bigquery_external_table_task', 'scheduled__2018-11-02T06:00:00+00:00', '--job-id', '1351', '--raw', '--subdir', 'DAGS_FOLDER/project_data_ingestion.py', '--cfg-path', '/tmp/tmp4y5q5t0d', '--error-file', '/tmp/tmpen2pqs9r']
[2022-03-26 10:54:49,512] {standard_task_runner.py:77} INFO - Job 1351: Subtask bigquery_external_table_task
[2022-03-26 10:54:49,620] {logging_mixin.py:109} INFO - Running <TaskInstance: dtc_project_ingest.bigquery_external_table_task scheduled__2018-11-02T06:00:00+00:00 [running]> on host c800f4dda314
[2022-03-26 10:54:49,753] {taskinstance.py:1426} INFO - Exporting the following env vars:
AIRFLOW_CTX_DAG_OWNER=***
AIRFLOW_CTX_DAG_ID=dtc_project_ingest
AIRFLOW_CTX_TASK_ID=bigquery_external_table_task
AIRFLOW_CTX_EXECUTION_DATE=2018-11-02T06:00:00+00:00
AIRFLOW_CTX_DAG_RUN_ID=scheduled__2018-11-02T06:00:00+00:00
[2022-03-26 10:54:49,757] {crypto.py:82} WARNING - empty cryptography key - values will not be stored encrypted.
[2022-03-26 10:54:51,459] {taskinstance.py:1277} INFO - Marking task as SUCCESS. dag_id=dtc_project_ingest, task_id=bigquery_external_table_task, execution_date=20181102T060000, start_date=20220326T105449, end_date=20220326T105451
[2022-03-26 10:54:51,505] {local_task_job.py:154} INFO - Task exited with return code 0
[2022-03-26 10:54:51,557] {local_task_job.py:264} INFO - 1 downstream tasks scheduled from follow-on schedule check
