[2022-03-21 22:49:22,231] {taskinstance.py:1032} INFO - Dependencies all met for <TaskInstance: dtc_project_ingest.local_to_gcs_task scheduled__2019-02-02T06:00:00+00:00 [queued]>
[2022-03-21 22:49:22,266] {taskinstance.py:1032} INFO - Dependencies all met for <TaskInstance: dtc_project_ingest.local_to_gcs_task scheduled__2019-02-02T06:00:00+00:00 [queued]>
[2022-03-21 22:49:22,268] {taskinstance.py:1238} INFO - 
--------------------------------------------------------------------------------
[2022-03-21 22:49:22,269] {taskinstance.py:1239} INFO - Starting attempt 1 of 2
[2022-03-21 22:49:22,271] {taskinstance.py:1240} INFO - 
--------------------------------------------------------------------------------
[2022-03-21 22:49:22,299] {taskinstance.py:1259} INFO - Executing <Task(PythonOperator): local_to_gcs_task> on 2019-02-02 06:00:00+00:00
[2022-03-21 22:49:22,308] {standard_task_runner.py:52} INFO - Started process 945 to run task
[2022-03-21 22:49:22,316] {standard_task_runner.py:76} INFO - Running: ['***', 'tasks', 'run', 'dtc_project_ingest', 'local_to_gcs_task', 'scheduled__2019-02-02T06:00:00+00:00', '--job-id', '533', '--raw', '--subdir', 'DAGS_FOLDER/project_data_ingestion.py', '--cfg-path', '/tmp/tmp2xd7rkd6', '--error-file', '/tmp/tmp2i3bzi7g']
[2022-03-21 22:49:22,336] {standard_task_runner.py:77} INFO - Job 533: Subtask local_to_gcs_task
[2022-03-21 22:49:22,460] {logging_mixin.py:109} INFO - Running <TaskInstance: dtc_project_ingest.local_to_gcs_task scheduled__2019-02-02T06:00:00+00:00 [running]> on host b91e76d7fa3b
[2022-03-21 22:49:22,529] {warnings.py:110} WARNING - /home/***/.local/lib/python3.7/site-packages/***/utils/context.py:152: AirflowContextDeprecationWarning: Accessing 'execution_date' from the template is deprecated and will be removed in a future version. Please use 'data_interval_start' or 'logical_date' instead.
  warnings.warn(_create_deprecation_warning(key, self._deprecation_replacements[key]))

[2022-03-21 22:49:22,580] {taskinstance.py:1426} INFO - Exporting the following env vars:
AIRFLOW_CTX_DAG_OWNER=***
AIRFLOW_CTX_DAG_ID=dtc_project_ingest
AIRFLOW_CTX_TASK_ID=local_to_gcs_task
AIRFLOW_CTX_EXECUTION_DATE=2019-02-02T06:00:00+00:00
AIRFLOW_CTX_DAG_RUN_ID=scheduled__2019-02-02T06:00:00+00:00
[2022-03-21 22:49:22,661] {taskinstance.py:1700} ERROR - Task failed with exception
Traceback (most recent call last):
  File "/home/airflow/.local/lib/python3.7/site-packages/airflow/models/taskinstance.py", line 1329, in _run_raw_task
    self._execute_task_with_callbacks(context)
  File "/home/airflow/.local/lib/python3.7/site-packages/airflow/models/taskinstance.py", line 1455, in _execute_task_with_callbacks
    result = self._execute_task(context, self.task)
  File "/home/airflow/.local/lib/python3.7/site-packages/airflow/models/taskinstance.py", line 1511, in _execute_task
    result = execute_callable(context=context)
  File "/home/airflow/.local/lib/python3.7/site-packages/airflow/operators/python.py", line 174, in execute
    return_value = self.execute_callable()
  File "/home/airflow/.local/lib/python3.7/site-packages/airflow/operators/python.py", line 185, in execute_callable
    return self.python_callable(*self.op_args, **self.op_kwargs)
  File "/opt/airflow/dags/project_data_ingestion.py", line 58, in upload_to_gcs
    blob.upload_from_filename(local_file)
  File "/home/airflow/.local/lib/python3.7/site-packages/google/cloud/storage/blob.py", line 2720, in upload_from_filename
    with open(filename, "rb") as file_obj:
FileNotFoundError: [Errno 2] No such file or directory: '/opt/airflow/2019-02-citibike-tripdata.parquet'
[2022-03-21 22:49:22,689] {taskinstance.py:1277} INFO - Marking task as UP_FOR_RETRY. dag_id=dtc_project_ingest, task_id=local_to_gcs_task, execution_date=20190202T060000, start_date=20220321T224922, end_date=20220321T224922
[2022-03-21 22:49:22,711] {standard_task_runner.py:92} ERROR - Failed to execute job 533 for task local_to_gcs_task
Traceback (most recent call last):
  File "/home/airflow/.local/lib/python3.7/site-packages/airflow/task/task_runner/standard_task_runner.py", line 85, in _start_by_fork
    args.func(args, dag=self.dag)
  File "/home/airflow/.local/lib/python3.7/site-packages/airflow/cli/cli_parser.py", line 48, in command
    return func(*args, **kwargs)
  File "/home/airflow/.local/lib/python3.7/site-packages/airflow/utils/cli.py", line 92, in wrapper
    return f(*args, **kwargs)
  File "/home/airflow/.local/lib/python3.7/site-packages/airflow/cli/commands/task_command.py", line 298, in task_run
    _run_task_by_selected_method(args, dag, ti)
  File "/home/airflow/.local/lib/python3.7/site-packages/airflow/cli/commands/task_command.py", line 107, in _run_task_by_selected_method
    _run_raw_task(args, ti)
  File "/home/airflow/.local/lib/python3.7/site-packages/airflow/cli/commands/task_command.py", line 184, in _run_raw_task
    error_file=args.error_file,
  File "/home/airflow/.local/lib/python3.7/site-packages/airflow/utils/session.py", line 70, in wrapper
    return func(*args, session=session, **kwargs)
  File "/home/airflow/.local/lib/python3.7/site-packages/airflow/models/taskinstance.py", line 1329, in _run_raw_task
    self._execute_task_with_callbacks(context)
  File "/home/airflow/.local/lib/python3.7/site-packages/airflow/models/taskinstance.py", line 1455, in _execute_task_with_callbacks
    result = self._execute_task(context, self.task)
  File "/home/airflow/.local/lib/python3.7/site-packages/airflow/models/taskinstance.py", line 1511, in _execute_task
    result = execute_callable(context=context)
  File "/home/airflow/.local/lib/python3.7/site-packages/airflow/operators/python.py", line 174, in execute
    return_value = self.execute_callable()
  File "/home/airflow/.local/lib/python3.7/site-packages/airflow/operators/python.py", line 185, in execute_callable
    return self.python_callable(*self.op_args, **self.op_kwargs)
  File "/opt/airflow/dags/project_data_ingestion.py", line 58, in upload_to_gcs
    blob.upload_from_filename(local_file)
  File "/home/airflow/.local/lib/python3.7/site-packages/google/cloud/storage/blob.py", line 2720, in upload_from_filename
    with open(filename, "rb") as file_obj:
FileNotFoundError: [Errno 2] No such file or directory: '/opt/airflow/2019-02-citibike-tripdata.parquet'
[2022-03-21 22:49:22,756] {local_task_job.py:154} INFO - Task exited with return code 1
[2022-03-21 22:49:22,817] {local_task_job.py:264} INFO - 0 downstream tasks scheduled from follow-on schedule check
[2022-03-21 23:00:41,901] {taskinstance.py:1032} INFO - Dependencies all met for <TaskInstance: dtc_project_ingest.local_to_gcs_task scheduled__2019-02-02T06:00:00+00:00 [queued]>
[2022-03-21 23:00:41,927] {taskinstance.py:1032} INFO - Dependencies all met for <TaskInstance: dtc_project_ingest.local_to_gcs_task scheduled__2019-02-02T06:00:00+00:00 [queued]>
[2022-03-21 23:00:41,929] {taskinstance.py:1238} INFO - 
--------------------------------------------------------------------------------
[2022-03-21 23:00:41,930] {taskinstance.py:1239} INFO - Starting attempt 1 of 2
[2022-03-21 23:00:41,931] {taskinstance.py:1240} INFO - 
--------------------------------------------------------------------------------
[2022-03-21 23:00:41,951] {taskinstance.py:1259} INFO - Executing <Task(PythonOperator): local_to_gcs_task> on 2019-02-02 06:00:00+00:00
[2022-03-21 23:00:41,958] {standard_task_runner.py:52} INFO - Started process 1528 to run task
[2022-03-21 23:00:41,964] {standard_task_runner.py:76} INFO - Running: ['***', 'tasks', 'run', 'dtc_project_ingest', 'local_to_gcs_task', 'scheduled__2019-02-02T06:00:00+00:00', '--job-id', '554', '--raw', '--subdir', 'DAGS_FOLDER/project_data_ingestion.py', '--cfg-path', '/tmp/tmpw8hhzw17', '--error-file', '/tmp/tmph0zxw2kk']
[2022-03-21 23:00:41,966] {standard_task_runner.py:77} INFO - Job 554: Subtask local_to_gcs_task
[2022-03-21 23:00:42,078] {logging_mixin.py:109} INFO - Running <TaskInstance: dtc_project_ingest.local_to_gcs_task scheduled__2019-02-02T06:00:00+00:00 [running]> on host b91e76d7fa3b
[2022-03-21 23:00:42,149] {warnings.py:110} WARNING - /home/***/.local/lib/python3.7/site-packages/***/utils/context.py:152: AirflowContextDeprecationWarning: Accessing 'execution_date' from the template is deprecated and will be removed in a future version. Please use 'data_interval_start' or 'logical_date' instead.
  warnings.warn(_create_deprecation_warning(key, self._deprecation_replacements[key]))

[2022-03-21 23:00:42,200] {taskinstance.py:1426} INFO - Exporting the following env vars:
AIRFLOW_CTX_DAG_OWNER=***
AIRFLOW_CTX_DAG_ID=dtc_project_ingest
AIRFLOW_CTX_TASK_ID=local_to_gcs_task
AIRFLOW_CTX_EXECUTION_DATE=2019-02-02T06:00:00+00:00
AIRFLOW_CTX_DAG_RUN_ID=scheduled__2019-02-02T06:00:00+00:00
[2022-03-21 23:00:42,219] {taskinstance.py:1700} ERROR - Task failed with exception
Traceback (most recent call last):
  File "/home/airflow/.local/lib/python3.7/site-packages/airflow/models/taskinstance.py", line 1329, in _run_raw_task
    self._execute_task_with_callbacks(context)
  File "/home/airflow/.local/lib/python3.7/site-packages/airflow/models/taskinstance.py", line 1455, in _execute_task_with_callbacks
    result = self._execute_task(context, self.task)
  File "/home/airflow/.local/lib/python3.7/site-packages/airflow/models/taskinstance.py", line 1511, in _execute_task
    result = execute_callable(context=context)
  File "/home/airflow/.local/lib/python3.7/site-packages/airflow/operators/python.py", line 174, in execute
    return_value = self.execute_callable()
  File "/home/airflow/.local/lib/python3.7/site-packages/airflow/operators/python.py", line 185, in execute_callable
    return self.python_callable(*self.op_args, **self.op_kwargs)
  File "/opt/airflow/dags/project_data_ingestion.py", line 59, in upload_to_gcs
    blob.upload_from_filename(local_file)
  File "/home/airflow/.local/lib/python3.7/site-packages/google/cloud/storage/blob.py", line 2720, in upload_from_filename
    with open(filename, "rb") as file_obj:
FileNotFoundError: [Errno 2] No such file or directory: '/opt/airflow/2019-02-citibike-tripdata.parquet'
[2022-03-21 23:00:42,244] {taskinstance.py:1277} INFO - Marking task as UP_FOR_RETRY. dag_id=dtc_project_ingest, task_id=local_to_gcs_task, execution_date=20190202T060000, start_date=20220321T230041, end_date=20220321T230042
[2022-03-21 23:00:42,269] {standard_task_runner.py:92} ERROR - Failed to execute job 554 for task local_to_gcs_task
Traceback (most recent call last):
  File "/home/airflow/.local/lib/python3.7/site-packages/airflow/task/task_runner/standard_task_runner.py", line 85, in _start_by_fork
    args.func(args, dag=self.dag)
  File "/home/airflow/.local/lib/python3.7/site-packages/airflow/cli/cli_parser.py", line 48, in command
    return func(*args, **kwargs)
  File "/home/airflow/.local/lib/python3.7/site-packages/airflow/utils/cli.py", line 92, in wrapper
    return f(*args, **kwargs)
  File "/home/airflow/.local/lib/python3.7/site-packages/airflow/cli/commands/task_command.py", line 298, in task_run
    _run_task_by_selected_method(args, dag, ti)
  File "/home/airflow/.local/lib/python3.7/site-packages/airflow/cli/commands/task_command.py", line 107, in _run_task_by_selected_method
    _run_raw_task(args, ti)
  File "/home/airflow/.local/lib/python3.7/site-packages/airflow/cli/commands/task_command.py", line 184, in _run_raw_task
    error_file=args.error_file,
  File "/home/airflow/.local/lib/python3.7/site-packages/airflow/utils/session.py", line 70, in wrapper
    return func(*args, session=session, **kwargs)
  File "/home/airflow/.local/lib/python3.7/site-packages/airflow/models/taskinstance.py", line 1329, in _run_raw_task
    self._execute_task_with_callbacks(context)
  File "/home/airflow/.local/lib/python3.7/site-packages/airflow/models/taskinstance.py", line 1455, in _execute_task_with_callbacks
    result = self._execute_task(context, self.task)
  File "/home/airflow/.local/lib/python3.7/site-packages/airflow/models/taskinstance.py", line 1511, in _execute_task
    result = execute_callable(context=context)
  File "/home/airflow/.local/lib/python3.7/site-packages/airflow/operators/python.py", line 174, in execute
    return_value = self.execute_callable()
  File "/home/airflow/.local/lib/python3.7/site-packages/airflow/operators/python.py", line 185, in execute_callable
    return self.python_callable(*self.op_args, **self.op_kwargs)
  File "/opt/airflow/dags/project_data_ingestion.py", line 59, in upload_to_gcs
    blob.upload_from_filename(local_file)
  File "/home/airflow/.local/lib/python3.7/site-packages/google/cloud/storage/blob.py", line 2720, in upload_from_filename
    with open(filename, "rb") as file_obj:
FileNotFoundError: [Errno 2] No such file or directory: '/opt/airflow/2019-02-citibike-tripdata.parquet'
[2022-03-21 23:00:42,300] {local_task_job.py:154} INFO - Task exited with return code 1
[2022-03-21 23:00:42,414] {local_task_job.py:264} INFO - 0 downstream tasks scheduled from follow-on schedule check
[2022-03-21 23:27:50,008] {taskinstance.py:1032} INFO - Dependencies all met for <TaskInstance: dtc_project_ingest.local_to_gcs_task scheduled__2019-02-02T06:00:00+00:00 [queued]>
[2022-03-21 23:27:50,029] {taskinstance.py:1032} INFO - Dependencies all met for <TaskInstance: dtc_project_ingest.local_to_gcs_task scheduled__2019-02-02T06:00:00+00:00 [queued]>
[2022-03-21 23:27:50,030] {taskinstance.py:1238} INFO - 
--------------------------------------------------------------------------------
[2022-03-21 23:27:50,031] {taskinstance.py:1239} INFO - Starting attempt 1 of 2
[2022-03-21 23:27:50,032] {taskinstance.py:1240} INFO - 
--------------------------------------------------------------------------------
[2022-03-21 23:27:50,051] {taskinstance.py:1259} INFO - Executing <Task(PythonOperator): local_to_gcs_task> on 2019-02-02 06:00:00+00:00
[2022-03-21 23:27:50,061] {standard_task_runner.py:52} INFO - Started process 2977 to run task
[2022-03-21 23:27:50,066] {standard_task_runner.py:76} INFO - Running: ['***', 'tasks', 'run', 'dtc_project_ingest', 'local_to_gcs_task', 'scheduled__2019-02-02T06:00:00+00:00', '--job-id', '607', '--raw', '--subdir', 'DAGS_FOLDER/project_data_ingestion.py', '--cfg-path', '/tmp/tmpt03qrdk1', '--error-file', '/tmp/tmpz9ye6t8_']
[2022-03-21 23:27:50,068] {standard_task_runner.py:77} INFO - Job 607: Subtask local_to_gcs_task
[2022-03-21 23:27:50,166] {logging_mixin.py:109} INFO - Running <TaskInstance: dtc_project_ingest.local_to_gcs_task scheduled__2019-02-02T06:00:00+00:00 [running]> on host b91e76d7fa3b
[2022-03-21 23:27:50,219] {warnings.py:110} WARNING - /home/***/.local/lib/python3.7/site-packages/***/utils/context.py:152: AirflowContextDeprecationWarning: Accessing 'execution_date' from the template is deprecated and will be removed in a future version. Please use 'data_interval_start' or 'logical_date' instead.
  warnings.warn(_create_deprecation_warning(key, self._deprecation_replacements[key]))

[2022-03-21 23:27:50,291] {taskinstance.py:1426} INFO - Exporting the following env vars:
AIRFLOW_CTX_DAG_OWNER=***
AIRFLOW_CTX_DAG_ID=dtc_project_ingest
AIRFLOW_CTX_TASK_ID=local_to_gcs_task
AIRFLOW_CTX_EXECUTION_DATE=2019-02-02T06:00:00+00:00
AIRFLOW_CTX_DAG_RUN_ID=scheduled__2019-02-02T06:00:00+00:00
[2022-03-21 23:28:23,889] {python.py:175} INFO - Done. Returned value was: None
[2022-03-21 23:28:23,904] {taskinstance.py:1277} INFO - Marking task as SUCCESS. dag_id=dtc_project_ingest, task_id=local_to_gcs_task, execution_date=20190202T060000, start_date=20220321T232750, end_date=20220321T232823
[2022-03-21 23:28:23,970] {local_task_job.py:154} INFO - Task exited with return code 0
[2022-03-21 23:28:24,035] {local_task_job.py:264} INFO - 1 downstream tasks scheduled from follow-on schedule check
[2022-03-23 09:05:00,728] {taskinstance.py:1032} INFO - Dependencies all met for <TaskInstance: dtc_project_ingest.local_to_gcs_task scheduled__2019-02-02T06:00:00+00:00 [queued]>
[2022-03-23 09:05:00,739] {taskinstance.py:1032} INFO - Dependencies all met for <TaskInstance: dtc_project_ingest.local_to_gcs_task scheduled__2019-02-02T06:00:00+00:00 [queued]>
[2022-03-23 09:05:00,740] {taskinstance.py:1238} INFO - 
--------------------------------------------------------------------------------
[2022-03-23 09:05:00,740] {taskinstance.py:1239} INFO - Starting attempt 1 of 2
[2022-03-23 09:05:00,742] {taskinstance.py:1240} INFO - 
--------------------------------------------------------------------------------
[2022-03-23 09:05:00,760] {taskinstance.py:1259} INFO - Executing <Task(PythonOperator): local_to_gcs_task> on 2019-02-02 06:00:00+00:00
[2022-03-23 09:05:00,769] {standard_task_runner.py:52} INFO - Started process 1099 to run task
[2022-03-23 09:05:00,773] {standard_task_runner.py:76} INFO - Running: ['***', 'tasks', 'run', 'dtc_project_ingest', 'local_to_gcs_task', 'scheduled__2019-02-02T06:00:00+00:00', '--job-id', '691', '--raw', '--subdir', 'DAGS_FOLDER/project_data_ingestion.py', '--cfg-path', '/tmp/tmpnofnfcw_', '--error-file', '/tmp/tmp5b0htzcp']
[2022-03-23 09:05:00,774] {standard_task_runner.py:77} INFO - Job 691: Subtask local_to_gcs_task
[2022-03-23 09:05:00,841] {logging_mixin.py:109} INFO - Running <TaskInstance: dtc_project_ingest.local_to_gcs_task scheduled__2019-02-02T06:00:00+00:00 [running]> on host 7127e26385ba
[2022-03-23 09:05:00,885] {warnings.py:110} WARNING - /home/***/.local/lib/python3.7/site-packages/***/utils/context.py:152: AirflowContextDeprecationWarning: Accessing 'execution_date' from the template is deprecated and will be removed in a future version. Please use 'data_interval_start' or 'logical_date' instead.
  warnings.warn(_create_deprecation_warning(key, self._deprecation_replacements[key]))

[2022-03-23 09:05:00,912] {taskinstance.py:1426} INFO - Exporting the following env vars:
AIRFLOW_CTX_DAG_OWNER=***
AIRFLOW_CTX_DAG_ID=dtc_project_ingest
AIRFLOW_CTX_TASK_ID=local_to_gcs_task
AIRFLOW_CTX_EXECUTION_DATE=2019-02-02T06:00:00+00:00
AIRFLOW_CTX_DAG_RUN_ID=scheduled__2019-02-02T06:00:00+00:00
[2022-03-23 09:05:42,558] {python.py:175} INFO - Done. Returned value was: None
[2022-03-23 09:05:42,622] {taskinstance.py:1277} INFO - Marking task as SUCCESS. dag_id=dtc_project_ingest, task_id=local_to_gcs_task, execution_date=20190202T060000, start_date=20220323T090500, end_date=20220323T090542
[2022-03-23 09:05:42,681] {local_task_job.py:154} INFO - Task exited with return code 0
[2022-03-23 09:05:42,718] {local_task_job.py:264} INFO - 1 downstream tasks scheduled from follow-on schedule check
[2022-03-23 16:06:31,527] {taskinstance.py:1032} INFO - Dependencies all met for <TaskInstance: dtc_project_ingest.local_to_gcs_task scheduled__2019-02-02T06:00:00+00:00 [queued]>
[2022-03-23 16:06:31,542] {taskinstance.py:1032} INFO - Dependencies all met for <TaskInstance: dtc_project_ingest.local_to_gcs_task scheduled__2019-02-02T06:00:00+00:00 [queued]>
[2022-03-23 16:06:31,543] {taskinstance.py:1238} INFO - 
--------------------------------------------------------------------------------
[2022-03-23 16:06:31,544] {taskinstance.py:1239} INFO - Starting attempt 1 of 2
[2022-03-23 16:06:31,546] {taskinstance.py:1240} INFO - 
--------------------------------------------------------------------------------
[2022-03-23 16:06:31,567] {taskinstance.py:1259} INFO - Executing <Task(PythonOperator): local_to_gcs_task> on 2019-02-02 06:00:00+00:00
[2022-03-23 16:06:31,574] {standard_task_runner.py:52} INFO - Started process 4149 to run task
[2022-03-23 16:06:31,586] {standard_task_runner.py:76} INFO - Running: ['***', 'tasks', 'run', 'dtc_project_ingest', 'local_to_gcs_task', 'scheduled__2019-02-02T06:00:00+00:00', '--job-id', '998', '--raw', '--subdir', 'DAGS_FOLDER/project_data_ingestion.py', '--cfg-path', '/tmp/tmppe1gd6ak', '--error-file', '/tmp/tmpjvjzjm3o']
[2022-03-23 16:06:31,589] {standard_task_runner.py:77} INFO - Job 998: Subtask local_to_gcs_task
[2022-03-23 16:06:31,685] {logging_mixin.py:109} INFO - Running <TaskInstance: dtc_project_ingest.local_to_gcs_task scheduled__2019-02-02T06:00:00+00:00 [running]> on host 7127e26385ba
[2022-03-23 16:06:31,756] {warnings.py:110} WARNING - /home/***/.local/lib/python3.7/site-packages/***/utils/context.py:152: AirflowContextDeprecationWarning: Accessing 'execution_date' from the template is deprecated and will be removed in a future version. Please use 'data_interval_start' or 'logical_date' instead.
  warnings.warn(_create_deprecation_warning(key, self._deprecation_replacements[key]))

[2022-03-23 16:06:31,802] {taskinstance.py:1426} INFO - Exporting the following env vars:
AIRFLOW_CTX_DAG_OWNER=***
AIRFLOW_CTX_DAG_ID=dtc_project_ingest
AIRFLOW_CTX_TASK_ID=local_to_gcs_task
AIRFLOW_CTX_EXECUTION_DATE=2019-02-02T06:00:00+00:00
AIRFLOW_CTX_DAG_RUN_ID=scheduled__2019-02-02T06:00:00+00:00
[2022-03-23 16:06:54,036] {python.py:175} INFO - Done. Returned value was: None
[2022-03-23 16:06:54,051] {taskinstance.py:1277} INFO - Marking task as SUCCESS. dag_id=dtc_project_ingest, task_id=local_to_gcs_task, execution_date=20190202T060000, start_date=20220323T160631, end_date=20220323T160654
[2022-03-23 16:06:54,091] {local_task_job.py:154} INFO - Task exited with return code 0
[2022-03-23 16:06:54,128] {local_task_job.py:264} INFO - 1 downstream tasks scheduled from follow-on schedule check
[2022-03-26 10:55:30,583] {taskinstance.py:1032} INFO - Dependencies all met for <TaskInstance: dtc_project_ingest.local_to_gcs_task scheduled__2019-02-02T06:00:00+00:00 [queued]>
[2022-03-26 10:55:30,602] {taskinstance.py:1032} INFO - Dependencies all met for <TaskInstance: dtc_project_ingest.local_to_gcs_task scheduled__2019-02-02T06:00:00+00:00 [queued]>
[2022-03-26 10:55:30,603] {taskinstance.py:1238} INFO - 
--------------------------------------------------------------------------------
[2022-03-26 10:55:30,605] {taskinstance.py:1239} INFO - Starting attempt 1 of 2
[2022-03-26 10:55:30,606] {taskinstance.py:1240} INFO - 
--------------------------------------------------------------------------------
[2022-03-26 10:55:30,627] {taskinstance.py:1259} INFO - Executing <Task(PythonOperator): local_to_gcs_task> on 2019-02-02 06:00:00+00:00
[2022-03-26 10:55:30,638] {standard_task_runner.py:52} INFO - Started process 6361 to run task
[2022-03-26 10:55:30,644] {standard_task_runner.py:76} INFO - Running: ['***', 'tasks', 'run', 'dtc_project_ingest', 'local_to_gcs_task', 'scheduled__2019-02-02T06:00:00+00:00', '--job-id', '1358', '--raw', '--subdir', 'DAGS_FOLDER/project_data_ingestion.py', '--cfg-path', '/tmp/tmpn7tp857v', '--error-file', '/tmp/tmpnrd7hqv7']
[2022-03-26 10:55:30,648] {standard_task_runner.py:77} INFO - Job 1358: Subtask local_to_gcs_task
[2022-03-26 10:55:30,746] {logging_mixin.py:109} INFO - Running <TaskInstance: dtc_project_ingest.local_to_gcs_task scheduled__2019-02-02T06:00:00+00:00 [running]> on host c800f4dda314
[2022-03-26 10:55:30,814] {warnings.py:110} WARNING - /home/***/.local/lib/python3.7/site-packages/***/utils/context.py:152: AirflowContextDeprecationWarning: Accessing 'execution_date' from the template is deprecated and will be removed in a future version. Please use 'data_interval_start' or 'logical_date' instead.
  warnings.warn(_create_deprecation_warning(key, self._deprecation_replacements[key]))

[2022-03-26 10:55:30,855] {taskinstance.py:1426} INFO - Exporting the following env vars:
AIRFLOW_CTX_DAG_OWNER=***
AIRFLOW_CTX_DAG_ID=dtc_project_ingest
AIRFLOW_CTX_TASK_ID=local_to_gcs_task
AIRFLOW_CTX_EXECUTION_DATE=2019-02-02T06:00:00+00:00
AIRFLOW_CTX_DAG_RUN_ID=scheduled__2019-02-02T06:00:00+00:00
[2022-03-26 10:56:52,842] {taskinstance.py:1700} ERROR - Task failed with exception
Traceback (most recent call last):
  File "/home/airflow/.local/lib/python3.7/site-packages/urllib3/connectionpool.py", line 706, in urlopen
    chunked=chunked,
  File "/home/airflow/.local/lib/python3.7/site-packages/urllib3/connectionpool.py", line 394, in _make_request
    conn.request(method, url, **httplib_request_kw)
  File "/home/airflow/.local/lib/python3.7/site-packages/urllib3/connection.py", line 239, in request
    super(HTTPConnection, self).request(method, url, body=body, headers=headers)
  File "/usr/local/lib/python3.7/http/client.py", line 1281, in request
    self._send_request(method, url, body, headers, encode_chunked)
  File "/usr/local/lib/python3.7/http/client.py", line 1327, in _send_request
    self.endheaders(body, encode_chunked=encode_chunked)
  File "/usr/local/lib/python3.7/http/client.py", line 1276, in endheaders
    self._send_output(message_body, encode_chunked=encode_chunked)
  File "/usr/local/lib/python3.7/http/client.py", line 1075, in _send_output
    self.send(chunk)
  File "/usr/local/lib/python3.7/http/client.py", line 997, in send
    self.sock.sendall(data)
  File "/usr/local/lib/python3.7/ssl.py", line 1034, in sendall
    v = self.send(byte_view[count:])
  File "/usr/local/lib/python3.7/ssl.py", line 1003, in send
    return self._sslobj.write(data)
socket.timeout: The write operation timed out

During handling of the above exception, another exception occurred:

Traceback (most recent call last):
  File "/home/airflow/.local/lib/python3.7/site-packages/requests/adapters.py", line 449, in send
    timeout=timeout
  File "/home/airflow/.local/lib/python3.7/site-packages/urllib3/connectionpool.py", line 756, in urlopen
    method, url, error=e, _pool=self, _stacktrace=sys.exc_info()[2]
  File "/home/airflow/.local/lib/python3.7/site-packages/urllib3/util/retry.py", line 532, in increment
    raise six.reraise(type(error), error, _stacktrace)
  File "/home/airflow/.local/lib/python3.7/site-packages/urllib3/packages/six.py", line 769, in reraise
    raise value.with_traceback(tb)
  File "/home/airflow/.local/lib/python3.7/site-packages/urllib3/connectionpool.py", line 706, in urlopen
    chunked=chunked,
  File "/home/airflow/.local/lib/python3.7/site-packages/urllib3/connectionpool.py", line 394, in _make_request
    conn.request(method, url, **httplib_request_kw)
  File "/home/airflow/.local/lib/python3.7/site-packages/urllib3/connection.py", line 239, in request
    super(HTTPConnection, self).request(method, url, body=body, headers=headers)
  File "/usr/local/lib/python3.7/http/client.py", line 1281, in request
    self._send_request(method, url, body, headers, encode_chunked)
  File "/usr/local/lib/python3.7/http/client.py", line 1327, in _send_request
    self.endheaders(body, encode_chunked=encode_chunked)
  File "/usr/local/lib/python3.7/http/client.py", line 1276, in endheaders
    self._send_output(message_body, encode_chunked=encode_chunked)
  File "/usr/local/lib/python3.7/http/client.py", line 1075, in _send_output
    self.send(chunk)
  File "/usr/local/lib/python3.7/http/client.py", line 997, in send
    self.sock.sendall(data)
  File "/usr/local/lib/python3.7/ssl.py", line 1034, in sendall
    v = self.send(byte_view[count:])
  File "/usr/local/lib/python3.7/ssl.py", line 1003, in send
    return self._sslobj.write(data)
urllib3.exceptions.ProtocolError: ('Connection aborted.', timeout('The write operation timed out'))

During handling of the above exception, another exception occurred:

Traceback (most recent call last):
  File "/home/airflow/.local/lib/python3.7/site-packages/airflow/models/taskinstance.py", line 1329, in _run_raw_task
    self._execute_task_with_callbacks(context)
  File "/home/airflow/.local/lib/python3.7/site-packages/airflow/models/taskinstance.py", line 1455, in _execute_task_with_callbacks
    result = self._execute_task(context, self.task)
  File "/home/airflow/.local/lib/python3.7/site-packages/airflow/models/taskinstance.py", line 1511, in _execute_task
    result = execute_callable(context=context)
  File "/home/airflow/.local/lib/python3.7/site-packages/airflow/operators/python.py", line 174, in execute
    return_value = self.execute_callable()
  File "/home/airflow/.local/lib/python3.7/site-packages/airflow/operators/python.py", line 185, in execute_callable
    return self.python_callable(*self.op_args, **self.op_kwargs)
  File "/opt/airflow/dags/project_data_ingestion.py", line 66, in upload_to_gcs
    blob.upload_from_filename(local_file)
  File "/home/airflow/.local/lib/python3.7/site-packages/google/cloud/storage/blob.py", line 2735, in upload_from_filename
    retry=retry,
  File "/home/airflow/.local/lib/python3.7/site-packages/google/cloud/storage/blob.py", line 2594, in upload_from_file
    retry=retry,
  File "/home/airflow/.local/lib/python3.7/site-packages/google/cloud/storage/blob.py", line 2412, in _do_upload
    retry=retry,
  File "/home/airflow/.local/lib/python3.7/site-packages/google/cloud/storage/blob.py", line 2242, in _do_resumable_upload
    response = upload.transmit_next_chunk(transport, timeout=timeout)
  File "/home/airflow/.local/lib/python3.7/site-packages/google/resumable_media/requests/upload.py", line 516, in transmit_next_chunk
    retriable_request, self._get_status_code, self._retry_strategy
  File "/home/airflow/.local/lib/python3.7/site-packages/google/resumable_media/requests/_request_helpers.py", line 170, in wait_and_retry
    raise error
  File "/home/airflow/.local/lib/python3.7/site-packages/google/resumable_media/requests/_request_helpers.py", line 147, in wait_and_retry
    response = func()
  File "/home/airflow/.local/lib/python3.7/site-packages/google/resumable_media/requests/upload.py", line 508, in retriable_request
    method, url, data=payload, headers=headers, timeout=timeout
  File "/home/airflow/.local/lib/python3.7/site-packages/google/auth/transport/requests.py", line 486, in request
    **kwargs
  File "/home/airflow/.local/lib/python3.7/site-packages/requests/sessions.py", line 542, in request
    resp = self.send(prep, **send_kwargs)
  File "/home/airflow/.local/lib/python3.7/site-packages/requests/sessions.py", line 655, in send
    r = adapter.send(request, **kwargs)
  File "/home/airflow/.local/lib/python3.7/site-packages/requests/adapters.py", line 498, in send
    raise ConnectionError(err, request=request)
requests.exceptions.ConnectionError: ('Connection aborted.', timeout('The write operation timed out'))
[2022-03-26 10:56:52,882] {taskinstance.py:1277} INFO - Marking task as UP_FOR_RETRY. dag_id=dtc_project_ingest, task_id=local_to_gcs_task, execution_date=20190202T060000, start_date=20220326T105530, end_date=20220326T105652
[2022-03-26 10:56:52,911] {standard_task_runner.py:92} ERROR - Failed to execute job 1358 for task local_to_gcs_task
Traceback (most recent call last):
  File "/home/airflow/.local/lib/python3.7/site-packages/urllib3/connectionpool.py", line 706, in urlopen
    chunked=chunked,
  File "/home/airflow/.local/lib/python3.7/site-packages/urllib3/connectionpool.py", line 394, in _make_request
    conn.request(method, url, **httplib_request_kw)
  File "/home/airflow/.local/lib/python3.7/site-packages/urllib3/connection.py", line 239, in request
    super(HTTPConnection, self).request(method, url, body=body, headers=headers)
  File "/usr/local/lib/python3.7/http/client.py", line 1281, in request
    self._send_request(method, url, body, headers, encode_chunked)
  File "/usr/local/lib/python3.7/http/client.py", line 1327, in _send_request
    self.endheaders(body, encode_chunked=encode_chunked)
  File "/usr/local/lib/python3.7/http/client.py", line 1276, in endheaders
    self._send_output(message_body, encode_chunked=encode_chunked)
  File "/usr/local/lib/python3.7/http/client.py", line 1075, in _send_output
    self.send(chunk)
  File "/usr/local/lib/python3.7/http/client.py", line 997, in send
    self.sock.sendall(data)
  File "/usr/local/lib/python3.7/ssl.py", line 1034, in sendall
    v = self.send(byte_view[count:])
  File "/usr/local/lib/python3.7/ssl.py", line 1003, in send
    return self._sslobj.write(data)
socket.timeout: The write operation timed out

During handling of the above exception, another exception occurred:

Traceback (most recent call last):
  File "/home/airflow/.local/lib/python3.7/site-packages/requests/adapters.py", line 449, in send
    timeout=timeout
  File "/home/airflow/.local/lib/python3.7/site-packages/urllib3/connectionpool.py", line 756, in urlopen
    method, url, error=e, _pool=self, _stacktrace=sys.exc_info()[2]
  File "/home/airflow/.local/lib/python3.7/site-packages/urllib3/util/retry.py", line 532, in increment
    raise six.reraise(type(error), error, _stacktrace)
  File "/home/airflow/.local/lib/python3.7/site-packages/urllib3/packages/six.py", line 769, in reraise
    raise value.with_traceback(tb)
  File "/home/airflow/.local/lib/python3.7/site-packages/urllib3/connectionpool.py", line 706, in urlopen
    chunked=chunked,
  File "/home/airflow/.local/lib/python3.7/site-packages/urllib3/connectionpool.py", line 394, in _make_request
    conn.request(method, url, **httplib_request_kw)
  File "/home/airflow/.local/lib/python3.7/site-packages/urllib3/connection.py", line 239, in request
    super(HTTPConnection, self).request(method, url, body=body, headers=headers)
  File "/usr/local/lib/python3.7/http/client.py", line 1281, in request
    self._send_request(method, url, body, headers, encode_chunked)
  File "/usr/local/lib/python3.7/http/client.py", line 1327, in _send_request
    self.endheaders(body, encode_chunked=encode_chunked)
  File "/usr/local/lib/python3.7/http/client.py", line 1276, in endheaders
    self._send_output(message_body, encode_chunked=encode_chunked)
  File "/usr/local/lib/python3.7/http/client.py", line 1075, in _send_output
    self.send(chunk)
  File "/usr/local/lib/python3.7/http/client.py", line 997, in send
    self.sock.sendall(data)
  File "/usr/local/lib/python3.7/ssl.py", line 1034, in sendall
    v = self.send(byte_view[count:])
  File "/usr/local/lib/python3.7/ssl.py", line 1003, in send
    return self._sslobj.write(data)
urllib3.exceptions.ProtocolError: ('Connection aborted.', timeout('The write operation timed out'))

During handling of the above exception, another exception occurred:

Traceback (most recent call last):
  File "/home/airflow/.local/lib/python3.7/site-packages/airflow/task/task_runner/standard_task_runner.py", line 85, in _start_by_fork
    args.func(args, dag=self.dag)
  File "/home/airflow/.local/lib/python3.7/site-packages/airflow/cli/cli_parser.py", line 48, in command
    return func(*args, **kwargs)
  File "/home/airflow/.local/lib/python3.7/site-packages/airflow/utils/cli.py", line 92, in wrapper
    return f(*args, **kwargs)
  File "/home/airflow/.local/lib/python3.7/site-packages/airflow/cli/commands/task_command.py", line 298, in task_run
    _run_task_by_selected_method(args, dag, ti)
  File "/home/airflow/.local/lib/python3.7/site-packages/airflow/cli/commands/task_command.py", line 107, in _run_task_by_selected_method
    _run_raw_task(args, ti)
  File "/home/airflow/.local/lib/python3.7/site-packages/airflow/cli/commands/task_command.py", line 184, in _run_raw_task
    error_file=args.error_file,
  File "/home/airflow/.local/lib/python3.7/site-packages/airflow/utils/session.py", line 70, in wrapper
    return func(*args, session=session, **kwargs)
  File "/home/airflow/.local/lib/python3.7/site-packages/airflow/models/taskinstance.py", line 1329, in _run_raw_task
    self._execute_task_with_callbacks(context)
  File "/home/airflow/.local/lib/python3.7/site-packages/airflow/models/taskinstance.py", line 1455, in _execute_task_with_callbacks
    result = self._execute_task(context, self.task)
  File "/home/airflow/.local/lib/python3.7/site-packages/airflow/models/taskinstance.py", line 1511, in _execute_task
    result = execute_callable(context=context)
  File "/home/airflow/.local/lib/python3.7/site-packages/airflow/operators/python.py", line 174, in execute
    return_value = self.execute_callable()
  File "/home/airflow/.local/lib/python3.7/site-packages/airflow/operators/python.py", line 185, in execute_callable
    return self.python_callable(*self.op_args, **self.op_kwargs)
  File "/opt/airflow/dags/project_data_ingestion.py", line 66, in upload_to_gcs
    blob.upload_from_filename(local_file)
  File "/home/airflow/.local/lib/python3.7/site-packages/google/cloud/storage/blob.py", line 2735, in upload_from_filename
    retry=retry,
  File "/home/airflow/.local/lib/python3.7/site-packages/google/cloud/storage/blob.py", line 2594, in upload_from_file
    retry=retry,
  File "/home/airflow/.local/lib/python3.7/site-packages/google/cloud/storage/blob.py", line 2412, in _do_upload
    retry=retry,
  File "/home/airflow/.local/lib/python3.7/site-packages/google/cloud/storage/blob.py", line 2242, in _do_resumable_upload
    response = upload.transmit_next_chunk(transport, timeout=timeout)
  File "/home/airflow/.local/lib/python3.7/site-packages/google/resumable_media/requests/upload.py", line 516, in transmit_next_chunk
    retriable_request, self._get_status_code, self._retry_strategy
  File "/home/airflow/.local/lib/python3.7/site-packages/google/resumable_media/requests/_request_helpers.py", line 170, in wait_and_retry
    raise error
  File "/home/airflow/.local/lib/python3.7/site-packages/google/resumable_media/requests/_request_helpers.py", line 147, in wait_and_retry
    response = func()
  File "/home/airflow/.local/lib/python3.7/site-packages/google/resumable_media/requests/upload.py", line 508, in retriable_request
    method, url, data=payload, headers=headers, timeout=timeout
  File "/home/airflow/.local/lib/python3.7/site-packages/google/auth/transport/requests.py", line 486, in request
    **kwargs
  File "/home/airflow/.local/lib/python3.7/site-packages/requests/sessions.py", line 542, in request
    resp = self.send(prep, **send_kwargs)
  File "/home/airflow/.local/lib/python3.7/site-packages/requests/sessions.py", line 655, in send
    r = adapter.send(request, **kwargs)
  File "/home/airflow/.local/lib/python3.7/site-packages/requests/adapters.py", line 498, in send
    raise ConnectionError(err, request=request)
requests.exceptions.ConnectionError: ('Connection aborted.', timeout('The write operation timed out'))
[2022-03-26 10:56:52,970] {local_task_job.py:154} INFO - Task exited with return code 1
[2022-03-26 10:56:53,034] {local_task_job.py:264} INFO - 0 downstream tasks scheduled from follow-on schedule check
[2022-03-26 15:33:22,231] {taskinstance.py:1032} INFO - Dependencies all met for <TaskInstance: dtc_project_ingest.local_to_gcs_task scheduled__2019-02-02T06:00:00+00:00 [queued]>
[2022-03-26 15:33:22,251] {taskinstance.py:1032} INFO - Dependencies all met for <TaskInstance: dtc_project_ingest.local_to_gcs_task scheduled__2019-02-02T06:00:00+00:00 [queued]>
[2022-03-26 15:33:22,253] {taskinstance.py:1238} INFO - 
--------------------------------------------------------------------------------
[2022-03-26 15:33:22,254] {taskinstance.py:1239} INFO - Starting attempt 1 of 2
[2022-03-26 15:33:22,255] {taskinstance.py:1240} INFO - 
--------------------------------------------------------------------------------
[2022-03-26 15:33:22,276] {taskinstance.py:1259} INFO - Executing <Task(PythonOperator): local_to_gcs_task> on 2019-02-02 06:00:00+00:00
[2022-03-26 15:33:22,288] {standard_task_runner.py:52} INFO - Started process 20304 to run task
[2022-03-26 15:33:22,293] {standard_task_runner.py:76} INFO - Running: ['***', 'tasks', 'run', 'dtc_project_ingest', 'local_to_gcs_task', 'scheduled__2019-02-02T06:00:00+00:00', '--job-id', '1598', '--raw', '--subdir', 'DAGS_FOLDER/project_data_ingestion.py', '--cfg-path', '/tmp/tmpovtfqa6k', '--error-file', '/tmp/tmpa3g_5vty']
[2022-03-26 15:33:22,295] {standard_task_runner.py:77} INFO - Job 1598: Subtask local_to_gcs_task
[2022-03-26 15:33:22,400] {logging_mixin.py:109} INFO - Running <TaskInstance: dtc_project_ingest.local_to_gcs_task scheduled__2019-02-02T06:00:00+00:00 [running]> on host c800f4dda314
[2022-03-26 15:33:22,459] {warnings.py:110} WARNING - /home/***/.local/lib/python3.7/site-packages/***/utils/context.py:152: AirflowContextDeprecationWarning: Accessing 'execution_date' from the template is deprecated and will be removed in a future version. Please use 'data_interval_start' or 'logical_date' instead.
  warnings.warn(_create_deprecation_warning(key, self._deprecation_replacements[key]))

[2022-03-26 15:33:22,491] {taskinstance.py:1426} INFO - Exporting the following env vars:
AIRFLOW_CTX_DAG_OWNER=***
AIRFLOW_CTX_DAG_ID=dtc_project_ingest
AIRFLOW_CTX_TASK_ID=local_to_gcs_task
AIRFLOW_CTX_EXECUTION_DATE=2019-02-02T06:00:00+00:00
AIRFLOW_CTX_DAG_RUN_ID=scheduled__2019-02-02T06:00:00+00:00
[2022-03-26 15:33:46,815] {python.py:175} INFO - Done. Returned value was: None
[2022-03-26 15:33:46,835] {taskinstance.py:1277} INFO - Marking task as SUCCESS. dag_id=dtc_project_ingest, task_id=local_to_gcs_task, execution_date=20190202T060000, start_date=20220326T153322, end_date=20220326T153346
[2022-03-26 15:33:46,873] {local_task_job.py:154} INFO - Task exited with return code 0
[2022-03-26 15:33:46,914] {local_task_job.py:264} INFO - 1 downstream tasks scheduled from follow-on schedule check
